<?xml version="1.0" ?>
<!-- =================================================================================== -->
<!-- |    This document was autogenerated by xacro from robot_8leg.xacro               | -->
<!-- |    EDITING THIS FILE BY HAND IS NOT RECOMMENDED                                 | -->
<!-- =================================================================================== -->

<robot name="robot_8wheel">
  <!-- ~~~~~~ -->
  <!-- macros -->
  <!-- ~~~~~~ -->
  <!-- make link -->
  <!--
    <xacro:make_cbox_link name = "Body4" xyz = "${body_x/2} 0 0" rpy = "0 0 0" mass = "${body_bound_m}" lx = "${body_x}" ly = "${body_y}" lz = "${body_z}" rgba="0 1.0 1.0 1.0" />
    <xacro:make_cbox_link name = "Body3" xyz = "${body_x/2} 0 0" rpy = "0 0 0" mass = "${body_m}" lx = "${body_x}" ly = "${body_y}" lz = "${body_z}" rgba="0 1.0 1.0 1.0" />
    <xacro:make_cbox_link name = "Body2" xyz = "${body_x/2} 0 0" rpy = "0 0 0" mass = "${body_m}" lx = "${body_x}" ly = "${body_y}" lz = "${body_z}" rgba="0 1.0 1.0 1.0" />
    -->
  <link name="Body1">
    <inertial>
      <origin rpy="0 0 0" xyz="0.25 0 0"/>
      <mass value="10.0"/>
      <inertia ixx="0.06283333333333334" ixy="0" ixz="0" iyy="0.22708333333333333" iyz="0" izz="0.2524166666666667"/>
    </inertial>
    <visual>
      <origin rpy="0 0 0" xyz="0.25 0 0"/>
      <geometry>
        <box size="0.5 0.23 0.15"/>
      </geometry>
      <material name="Body1_material">
        <color rgba="0 1.0 1.0 1.0"/>
      </material>
    </visual>
    <collision>
      <origin rpy="0 0 0" xyz="0.25 0 0"/>
      <geometry>
        <box size="0.5 0.23 0.15"/>
      </geometry>
    </collision>
  </link>
  <link name="conct0a">
    <inertial>
      <origin rpy="0 -1.57075 0" xyz=" 0.02 0 0"/>
      <mass value="0.05"/>
      <inertia ixx="5.1666666666666664e-05" ixy="0" ixz="0" iyy="5.1666666666666664e-05" iyz="0" izz="8.999999999999999e-05"/>
    </inertial>
    <visual>
      <origin rpy="0 -1.57075 0" xyz=" 0.02 0 0"/>
      <geometry>
        <cylinder length="0.04" radius="0.06"/>
      </geometry>
      <material name="conct0a_material">
        <color rgba="0 0.0 0.8 1.0"/>
      </material>
    </visual>
    <collision>
      <origin rpy="0 -1.57075 0" xyz=" 0.02 0 0"/>
      <geometry>
        <cylinder length="0.04" radius="0.06"/>
      </geometry>
    </collision>
  </link>
  <link name="conct0b">
    <inertial>
      <origin rpy="0 -1.57075 0" xyz=" 0.02 0 0"/>
      <mass value="0.05"/>
      <inertia ixx="5.1666666666666664e-05" ixy="0" ixz="0" iyy="5.1666666666666664e-05" iyz="0" izz="8.999999999999999e-05"/>
    </inertial>
    <visual>
      <origin rpy="0 -1.57075 0" xyz=" 0.02 0 0"/>
      <geometry>
        <cylinder length="0.04" radius="0.06"/>
      </geometry>
      <material name="conct0b_material">
        <color rgba="0 0.0 0.8 1.0"/>
      </material>
    </visual>
    <collision>
      <origin rpy="0 -1.57075 0" xyz=" 0.02 0 0"/>
      <geometry>
        <cylinder length="0.04" radius="0.06"/>
      </geometry>
    </collision>
  </link>
  <link name="Body0">
    <inertial>
      <origin rpy="0 0 0" xyz="0.25 0 0"/>
      <mass value="10.0"/>
      <inertia ixx="0.06283333333333334" ixy="0" ixz="0" iyy="0.22708333333333333" iyz="0" izz="0.2524166666666667"/>
    </inertial>
    <visual>
      <origin rpy="0 0 0" xyz="0.25 0 0"/>
      <geometry>
        <box size="0.5 0.23 0.15"/>
      </geometry>
      <material name="Body0_material">
        <color rgba="0 1.0 1.0 1.0"/>
      </material>
    </visual>
    <collision>
      <origin rpy="0 0 0" xyz="0.25 0 0"/>
      <geometry>
        <box size="0.5 0.23 0.15"/>
      </geometry>
    </collision>
  </link>
  <joint name="Torso01" type="fixed">
    <parent link="Body1"/>
    <child link="conct0b"/>
    <origin xyz="0.5 0 0"/>
  </joint>
  <joint name="torso" type="continuous">
    <parent link="conct0b"/>
    <child link="conct0a"/>
    <origin xyz="0.04 0 0"/>
    <axis xyz="0 1 0"/>
    <calibration rising="0.0"/>
    <dynamics damping="0" friction="0"/>
  </joint>
  <transmission name="tran_torso">
    <type>transmission_interface/SimpleTransmission</type>
    <joint name="torso">
      <hardwareInterface>hardware_interface/EffortJointInterface</hardwareInterface>
    </joint>
    <actuator name="motor_torso">
      <hardwareInterface>hardware_interface/EffortJointInterface</hardwareInterface>
      <mechanicalReduction>1</mechanicalReduction>
    </actuator>
  </transmission>
  <joint name="Torso00" type="fixed">
    <parent link="conct0a"/>
    <child link="Body0"/>
    <origin xyz="0.04 0 0"/>
  </joint>
  <link name="lr0_coxa">
    <inertial>
      <origin rpy="1.57075 0 0" xyz="0 -0.07 0"/>
      <mass value="0.5"/>
      <inertia ixx="0.0012666666666666668" ixy="0" ixz="0" iyy="0.0012666666666666668" iyz="0" izz="0.0009"/>
    </inertial>
    <visual>
      <origin rpy="1.57075 0 0" xyz="0 -0.07 0"/>
      <geometry>
        <cylinder length="0.14" radius="0.06"/>
      </geometry>
      <material name="lr0_coxa_material">
        <color rgba="0 0.0 1.0 1.0"/>
      </material>
    </visual>
    <collision>
      <origin rpy="1.57075 0 0" xyz="0 -0.07 0"/>
      <geometry>
        <cylinder length="0.14" radius="0.06"/>
      </geometry>
    </collision>
  </link>
  <link name="lr0_femur">
    <inertial>
      <origin rpy="1.57075 0 0" xyz="0 -0.14 0"/>
      <mass value="3.0"/>
      <inertia ixx="0.022300000000000004" ixy="0" ixz="0" iyy="0.022300000000000004" iyz="0" izz="0.005399999999999999"/>
    </inertial>
    <visual>
      <origin rpy="1.57075 0 0" xyz="0 -0.14 0"/>
      <geometry>
        <cylinder length="0.28" radius="0.06"/>
      </geometry>
      <material name="lr0_femur_material">
        <color rgba="0 0.0 0.8 1.0"/>
      </material>
    </visual>
    <collision>
      <origin rpy="1.57075 0 0" xyz="0 -0.14 0"/>
      <geometry>
        <cylinder length="0.28" radius="0.06"/>
      </geometry>
    </collision>
  </link>
  <link name="lr0_tibia">
    <inertial>
      <origin rpy="1.57075 0 0" xyz="0 -0.07 0"/>
      <mass value="0.5"/>
      <inertia ixx="0.0012666666666666668" ixy="0" ixz="0" iyy="0.0012666666666666668" iyz="0" izz="0.0009"/>
    </inertial>
    <visual>
      <origin rpy="1.57075 0 0" xyz="0 -0.07 0"/>
      <geometry>
        <cylinder length="0.14" radius="0.06"/>
      </geometry>
      <material name="lr0_tibia_material">
        <color rgba="0 0.0 0.6 1.0"/>
      </material>
    </visual>
    <collision>
      <origin rpy="1.57075 0 0" xyz="0 -0.07 0"/>
      <geometry>
        <cylinder length="0.14" radius="0.06"/>
      </geometry>
    </collision>
  </link>
  <link name="lr0_wheel">
    <inertial>
      <origin rpy="1.57075 0 0" xyz="0 -0.05 0"/>
      <mass value="0.3"/>
      <inertia ixx="0.004046875" ixy="0" ixz="0" iyy="0.004046875" iyz="0" izz="0.007593750000000001"/>
    </inertial>
    <visual>
      <origin rpy="1.57075 0 0" xyz="0 -0.05 0"/>
      <geometry>
        <cylinder length="0.1" radius="0.125"/>
      </geometry>
      <material name="lr0_wheel_material">
        <color rgba="0 0.5 1.0 1.0"/>
      </material>
    </visual>
    <collision>
      <origin rpy="1.57075 0 0" xyz="0 -0.05 0"/>
      <geometry>
        <cylinder length="0.1" radius="0.125"/>
      </geometry>
    </collision>
  </link>

  <joint name="lr0_tc" type="continuous">
    <parent link="Body0"/>
    <child link="lr0_coxa"/>
    <origin xyz="0.39 -0.115 0"/>
    <axis xyz="0 1 0"/>
    <calibration rising="0.0"/>
    <dynamics damping="0" friction="0"/>
  </joint>
  <transmission name="tran_lr0_tc">
    <type>transmission_interface/SimpleTransmission</type>
    <joint name="lr0_tc">
      <hardwareInterface>hardware_interface/EffortJointInterface</hardwareInterface>
    </joint>
    <actuator name="motor_lr0_tc">
      <hardwareInterface>hardware_interface/EffortJointInterface</hardwareInterface>
      <mechanicalReduction>1</mechanicalReduction>
    </actuator>
  </transmission>
  <joint name="lr0_ct" type="continuous">
    <parent link="lr0_coxa"/>
    <child link="lr0_femur"/>
    <origin xyz="0 -0.14 0"/>
    <axis xyz="1 0 0"/>
    <calibration rising="0.0"/>
    <dynamics damping="0" friction="0"/>
  </joint>
  <transmission name="tran_lr0_ct">
    <type>transmission_interface/SimpleTransmission</type>
    <joint name="lr0_ct">
      <hardwareInterface>hardware_interface/EffortJointInterface</hardwareInterface>
    </joint>
    <actuator name="motor_lr0_ct">
      <hardwareInterface>hardware_interface/EffortJointInterface</hardwareInterface>
      <mechanicalReduction>1</mechanicalReduction>
    </actuator>
  </transmission>
  <joint name="lr0_ft" type="continuous">
    <parent link="lr0_femur"/>
    <child link="lr0_tibia"/>
    <origin xyz="0 -0.28 0"/>
    <axis xyz="1 0 0"/>
    <calibration rising="0.0"/>
    <dynamics damping="0" friction="0"/>
  </joint>
  <transmission name="tran_lr0_ft">
    <type>transmission_interface/SimpleTransmission</type>
    <joint name="lr0_ft">
      <hardwareInterface>hardware_interface/EffortJointInterface</hardwareInterface>
    </joint>
    <actuator name="motor_lr0_ft">
      <hardwareInterface>hardware_interface/EffortJointInterface</hardwareInterface>
      <mechanicalReduction>1</mechanicalReduction>
    </actuator>
  </transmission>
  <joint name="lr0_wh" type="continuous">
    <parent link="lr0_tibia"/>
    <child link="lr0_wheel"/>
    <origin xyz="0 -0.14 0"/>
    <axis xyz="0 1 0"/>
    <calibration rising="0.0"/>
    <dynamics damping="0" friction="0"/>
  </joint>
  <transmission name="tran_lr0_wh">
    <type>transmission_interface/SimpleTransmission</type>
    <joint name="lr0_wh">
      <hardwareInterface>hardware_interface/EffortJointInterface</hardwareInterface>
    </joint>
    <actuator name="motor_lr0_wh">
      <hardwareInterface>hardware_interface/EffortJointInterface</hardwareInterface>
      <mechanicalReduction>1</mechanicalReduction>
    </actuator>
  </transmission>

  <link name="ll0_coxa">
    <inertial>
      <origin rpy="-1.57075 0 0" xyz="0 0.07 0"/>
      <mass value="0.5"/>
      <inertia ixx="0.0012666666666666668" ixy="0" ixz="0" iyy="0.0012666666666666668" iyz="0" izz="0.0009"/>
    </inertial>
    <visual>
      <origin rpy="-1.57075 0 0" xyz="0 0.07 0"/>
      <geometry>
        <cylinder length="0.14" radius="0.06"/>
      </geometry>
      <material name="ll0_coxa_material">
        <color rgba="0 0.0 1.0 1.0"/>
      </material>
    </visual>
    <collision>
      <origin rpy="-1.57075 0 0" xyz="0 0.07 0"/>
      <geometry>
        <cylinder length="0.14" radius="0.06"/>
      </geometry>
    </collision>
  </link>
  <link name="ll0_femur">
    <inertial>
      <origin rpy="-1.57075 0 0" xyz="0 0.14 0"/>
      <mass value="3.0"/>
      <inertia ixx="0.022300000000000004" ixy="0" ixz="0" iyy="0.022300000000000004" iyz="0" izz="0.005399999999999999"/>
    </inertial>
    <visual>
      <origin rpy="-1.57075 0 0" xyz="0 0.14 0"/>
      <geometry>
        <cylinder length="0.28" radius="0.06"/>
      </geometry>
      <material name="ll0_femur_material">
        <color rgba="0 0.0 0.8 1.0"/>
      </material>
    </visual>
    <collision>
      <origin rpy="-1.57075 0 0" xyz="0 0.14 0"/>
      <geometry>
        <cylinder length="0.28" radius="0.06"/>
      </geometry>
    </collision>
  </link>
  <link name="ll0_tibia">
    <inertial>
      <origin rpy="-1.57075 0 0" xyz="0 0.07 0"/>
      <mass value="0.5"/>
      <inertia ixx="0.0012666666666666668" ixy="0" ixz="0" iyy="0.0012666666666666668" iyz="0" izz="0.0009"/>
    </inertial>
    <visual>
      <origin rpy="-1.57075 0 0" xyz="0 0.07 0"/>
      <geometry>
        <cylinder length="0.14" radius="0.06"/>
      </geometry>
      <material name="ll0_tibia_material">
        <color rgba="0 0.0 0.6 1.0"/>
      </material>
    </visual>
    <collision>
      <origin rpy="-1.57075 0 0" xyz="0 0.07 0"/>
      <geometry>
        <cylinder length="0.14" radius="0.06"/>
      </geometry>
    </collision>
  </link>
  <link name="ll0_wheel">
    <inertial>
      <origin rpy="-1.57075 0 0" xyz="0 0.05 0"/>
      <mass value="0.3"/>
      <inertia ixx="0.004046875" ixy="0" ixz="0" iyy="0.004046875" iyz="0" izz="0.007593750000000001"/>
    </inertial>
    <visual>
      <origin rpy="-1.57075 0 0" xyz="0 0.05 0"/>
      <geometry>
        <cylinder length="0.1" radius="0.125"/>
      </geometry>
      <material name="ll0_wheel_material">
        <color rgba="0 0.5 1.0 1.0"/>
      </material>
    </visual>
    <collision>
      <origin rpy="-1.57075 0 0" xyz="0 0.05 0"/>
      <geometry>
        <cylinder length="0.1" radius="0.125"/>
      </geometry>
    </collision>
  </link>

  <joint name="ll0_tc" type="continuous">
    <parent link="Body0"/>
    <child link="ll0_coxa"/>
    <origin xyz="0.39 0.115 0"/>
    <axis xyz="0 1 0"/>
    <calibration rising="0.0"/>
    <dynamics damping="0" friction="0"/>
  </joint>
  <transmission name="tran_ll0_tc">
    <type>transmission_interface/SimpleTransmission</type>
    <joint name="ll0_tc">
      <hardwareInterface>hardware_interface/EffortJointInterface</hardwareInterface>
    </joint>
    <actuator name="motor_ll0_tc">
      <hardwareInterface>hardware_interface/EffortJointInterface</hardwareInterface>
      <mechanicalReduction>1</mechanicalReduction>
    </actuator>
  </transmission>
  <joint name="ll0_ct" type="continuous">
    <parent link="ll0_coxa"/>
    <child link="ll0_femur"/>
    <origin xyz="0 0.14 0"/>
    <axis xyz="1 0 0"/>
    <calibration rising="0.0"/>
    <dynamics damping="0" friction="0"/>
  </joint>
  <transmission name="tran_ll0_ct">
    <type>transmission_interface/SimpleTransmission</type>
    <joint name="ll0_ct">
      <hardwareInterface>hardware_interface/EffortJointInterface</hardwareInterface>
    </joint>
    <actuator name="motor_ll0_ct">
      <hardwareInterface>hardware_interface/EffortJointInterface</hardwareInterface>
      <mechanicalReduction>1</mechanicalReduction>
    </actuator>
  </transmission>
  <joint name="ll0_ft" type="continuous">
    <parent link="ll0_femur"/>
    <child link="ll0_tibia"/>
    <origin xyz="0 0.28 0"/>
    <axis xyz="1 0 0"/>
    <calibration rising="0.0"/>
    <dynamics damping="0" friction="0"/>
  </joint>
  <transmission name="tran_ll0_ft">
    <type>transmission_interface/SimpleTransmission</type>
    <joint name="ll0_ft">
      <hardwareInterface>hardware_interface/EffortJointInterface</hardwareInterface>
    </joint>
    <actuator name="motor_ll0_ft">
      <hardwareInterface>hardware_interface/EffortJointInterface</hardwareInterface>
      <mechanicalReduction>1</mechanicalReduction>
    </actuator>
  </transmission>
  <joint name="ll0_wh" type="continuous">
    <parent link="ll0_tibia"/>
    <child link="ll0_wheel"/>
    <origin xyz="0 0.14 0"/>
    <axis xyz="0 1 0"/>
    <calibration rising="0.0"/>
    <dynamics damping="0" friction="0"/>
  </joint>
  <transmission name="tran_ll0_wh">
    <type>transmission_interface/SimpleTransmission</type>
    <joint name="ll0_wh">
      <hardwareInterface>hardware_interface/EffortJointInterface</hardwareInterface>
    </joint>
    <actuator name="motor_ll0_wh">
      <hardwareInterface>hardware_interface/EffortJointInterface</hardwareInterface>
      <mechanicalReduction>1</mechanicalReduction>
    </actuator>
  </transmission>

  <link name="lr1_coxa">
    <inertial>
      <origin rpy="1.57075 0 0" xyz="0 -0.07 0"/>
      <mass value="0.5"/>
      <inertia ixx="0.0012666666666666668" ixy="0" ixz="0" iyy="0.0012666666666666668" iyz="0" izz="0.0009"/>
    </inertial>
    <visual>
      <origin rpy="1.57075 0 0" xyz="0 -0.07 0"/>
      <geometry>
        <cylinder length="0.14" radius="0.06"/>
      </geometry>
      <material name="lr1_coxa_material">
        <color rgba="0 0.0 1.0 1.0"/>
      </material>
    </visual>
    <collision>
      <origin rpy="1.57075 0 0" xyz="0 -0.07 0"/>
      <geometry>
        <cylinder length="0.14" radius="0.06"/>
      </geometry>
    </collision>
  </link>
  <link name="lr1_femur">
    <inertial>
      <origin rpy="1.57075 0 0" xyz="0 -0.14 0"/>
      <mass value="3.0"/>
      <inertia ixx="0.022300000000000004" ixy="0" ixz="0" iyy="0.022300000000000004" iyz="0" izz="0.005399999999999999"/>
    </inertial>
    <visual>
      <origin rpy="1.57075 0 0" xyz="0 -0.14 0"/>
      <geometry>
        <cylinder length="0.28" radius="0.06"/>
      </geometry>
      <material name="lr1_femur_material">
        <color rgba="0 0.0 0.8 1.0"/>
      </material>
    </visual>
    <collision>
      <origin rpy="1.57075 0 0" xyz="0 -0.14 0"/>
      <geometry>
        <cylinder length="0.28" radius="0.06"/>
      </geometry>
    </collision>
  </link>
  <link name="lr1_tibia">
    <inertial>
      <origin rpy="1.57075 0 0" xyz="0 -0.07 0"/>
      <mass value="0.5"/>
      <inertia ixx="0.0012666666666666668" ixy="0" ixz="0" iyy="0.0012666666666666668" iyz="0" izz="0.0009"/>
    </inertial>
    <visual>
      <origin rpy="1.57075 0 0" xyz="0 -0.07 0"/>
      <geometry>
        <cylinder length="0.14" radius="0.06"/>
      </geometry>
      <material name="lr1_tibia_material">
        <color rgba="0 0.0 0.6 1.0"/>
      </material>
    </visual>
    <collision>
      <origin rpy="1.57075 0 0" xyz="0 -0.07 0"/>
      <geometry>
        <cylinder length="0.14" radius="0.06"/>
      </geometry>
    </collision>
  </link>
  <link name="lr1_wheel">
    <inertial>
      <origin rpy="1.57075 0 0" xyz="0 -0.05 0"/>
      <mass value="0.3"/>
      <inertia ixx="0.004046875" ixy="0" ixz="0" iyy="0.004046875" iyz="0" izz="0.007593750000000001"/>
    </inertial>
    <visual>
      <origin rpy="1.57075 0 0" xyz="0 -0.05 0"/>
      <geometry>
        <cylinder length="0.1" radius="0.125"/>
      </geometry>
      <material name="lr1_wheel_material">
        <color rgba="0 0.5 1.0 1.0"/>
      </material>
    </visual>
    <collision>
      <origin rpy="1.57075 0 0" xyz="0 -0.05 0"/>
      <geometry>
        <cylinder length="0.1" radius="0.125"/>
      </geometry>
    </collision>
  </link>

  <joint name="lr1_tc" type="continuous">
    <parent link="Body0"/>
    <child link="lr1_coxa"/>
    <origin xyz="0.11 -0.115 0"/>
    <axis xyz="0 1 0"/>
    <calibration rising="0.0"/>
    <dynamics damping="0" friction="0"/>
  </joint>
  <transmission name="tran_lr1_tc">
    <type>transmission_interface/SimpleTransmission</type>
    <joint name="lr1_tc">
      <hardwareInterface>hardware_interface/EffortJointInterface</hardwareInterface>
    </joint>
    <actuator name="motor_lr1_tc">
      <hardwareInterface>hardware_interface/EffortJointInterface</hardwareInterface>
      <mechanicalReduction>1</mechanicalReduction>
    </actuator>
  </transmission>
  <joint name="lr1_ct" type="continuous">
    <parent link="lr1_coxa"/>
    <child link="lr1_femur"/>
    <origin xyz="0 -0.14 0"/>
    <axis xyz="1 0 0"/>
    <calibration rising="0.0"/>
    <dynamics damping="0" friction="0"/>
  </joint>
  <transmission name="tran_lr1_ct">
    <type>transmission_interface/SimpleTransmission</type>
    <joint name="lr1_ct">
      <hardwareInterface>hardware_interface/EffortJointInterface</hardwareInterface>
    </joint>
    <actuator name="motor_lr1_ct">
      <hardwareInterface>hardware_interface/EffortJointInterface</hardwareInterface>
      <mechanicalReduction>1</mechanicalReduction>
    </actuator>
  </transmission>
  <joint name="lr1_ft" type="continuous">
    <parent link="lr1_femur"/>
    <child link="lr1_tibia"/>
    <origin xyz="0 -0.28 0"/>
    <axis xyz="1 0 0"/>
    <calibration rising="0.0"/>
    <dynamics damping="0" friction="0"/>
  </joint>
  <transmission name="tran_lr1_ft">
    <type>transmission_interface/SimpleTransmission</type>
    <joint name="lr1_ft">
      <hardwareInterface>hardware_interface/EffortJointInterface</hardwareInterface>
    </joint>
    <actuator name="motor_lr1_ft">
      <hardwareInterface>hardware_interface/EffortJointInterface</hardwareInterface>
      <mechanicalReduction>1</mechanicalReduction>
    </actuator>
  </transmission>
  <joint name="lr1_wh" type="continuous">
    <parent link="lr1_tibia"/>
    <child link="lr1_wheel"/>
    <origin xyz="0 -0.14 0"/>
    <axis xyz="0 1 0"/>
    <calibration rising="0.0"/>
    <dynamics damping="0" friction="0"/>
  </joint>
  <transmission name="tran_lr1_wh">
    <type>transmission_interface/SimpleTransmission</type>
    <joint name="lr1_wh">
      <hardwareInterface>hardware_interface/EffortJointInterface</hardwareInterface>
    </joint>
    <actuator name="motor_lr1_wh">
      <hardwareInterface>hardware_interface/EffortJointInterface</hardwareInterface>
      <mechanicalReduction>1</mechanicalReduction>
    </actuator>
  </transmission>

  <link name="ll1_coxa">
    <inertial>
      <origin rpy="-1.57075 0 0" xyz="0 0.07 0"/>
      <mass value="0.5"/>
      <inertia ixx="0.0012666666666666668" ixy="0" ixz="0" iyy="0.0012666666666666668" iyz="0" izz="0.0009"/>
    </inertial>
    <visual>
      <origin rpy="-1.57075 0 0" xyz="0 0.07 0"/>
      <geometry>
        <cylinder length="0.14" radius="0.06"/>
      </geometry>
      <material name="ll1_coxa_material">
        <color rgba="0 0.0 1.0 1.0"/>
      </material>
    </visual>
    <collision>
      <origin rpy="-1.57075 0 0" xyz="0 0.07 0"/>
      <geometry>
        <cylinder length="0.14" radius="0.06"/>
      </geometry>
    </collision>
  </link>
  <link name="ll1_femur">
    <inertial>
      <origin rpy="-1.57075 0 0" xyz="0 0.14 0"/>
      <mass value="3.0"/>
      <inertia ixx="0.022300000000000004" ixy="0" ixz="0" iyy="0.022300000000000004" iyz="0" izz="0.005399999999999999"/>
    </inertial>
    <visual>
      <origin rpy="-1.57075 0 0" xyz="0 0.14 0"/>
      <geometry>
        <cylinder length="0.28" radius="0.06"/>
      </geometry>
      <material name="ll1_femur_material">
        <color rgba="0 0.0 0.8 1.0"/>
      </material>
    </visual>
    <collision>
      <origin rpy="-1.57075 0 0" xyz="0 0.14 0"/>
      <geometry>
        <cylinder length="0.28" radius="0.06"/>
      </geometry>
    </collision>
  </link>
  <link name="ll1_tibia">
    <inertial>
      <origin rpy="-1.57075 0 0" xyz="0 0.07 0"/>
      <mass value="0.5"/>
      <inertia ixx="0.0012666666666666668" ixy="0" ixz="0" iyy="0.0012666666666666668" iyz="0" izz="0.0009"/>
    </inertial>
    <visual>
      <origin rpy="-1.57075 0 0" xyz="0 0.07 0"/>
      <geometry>
        <cylinder length="0.14" radius="0.06"/>
      </geometry>
      <material name="ll1_tibia_material">
        <color rgba="0 0.0 0.6 1.0"/>
      </material>
    </visual>
    <collision>
      <origin rpy="-1.57075 0 0" xyz="0 0.07 0"/>
      <geometry>
        <cylinder length="0.14" radius="0.06"/>
      </geometry>
    </collision>
  </link>
  <link name="ll1_wheel">
    <inertial>
      <origin rpy="-1.57075 0 0" xyz="0 0.05 0"/>
      <mass value="0.3"/>
      <inertia ixx="0.004046875" ixy="0" ixz="0" iyy="0.004046875" iyz="0" izz="0.007593750000000001"/>
    </inertial>
    <visual>
      <origin rpy="-1.57075 0 0" xyz="0 0.05 0"/>
      <geometry>
        <cylinder length="0.1" radius="0.125"/>
      </geometry>
      <material name="ll1_wheel_material">
        <color rgba="0 0.5 1.0 1.0"/>
      </material>
    </visual>
    <collision>
      <origin rpy="-1.57075 0 0" xyz="0 0.05 0"/>
      <geometry>
        <cylinder length="0.1" radius="0.125"/>
      </geometry>
    </collision>
  </link>

  <joint name="ll1_tc" type="continuous">
    <parent link="Body0"/>
    <child link="ll1_coxa"/>
    <origin xyz="0.11 0.115 0"/>
    <axis xyz="0 1 0"/>
    <calibration rising="0.0"/>
    <dynamics damping="0" friction="0"/>
  </joint>
  <transmission name="tran_ll1_tc">
    <type>transmission_interface/SimpleTransmission</type>
    <joint name="ll1_tc">
      <hardwareInterface>hardware_interface/EffortJointInterface</hardwareInterface>
    </joint>
    <actuator name="motor_ll1_tc">
      <hardwareInterface>hardware_interface/EffortJointInterface</hardwareInterface>
      <mechanicalReduction>1</mechanicalReduction>
    </actuator>
  </transmission>
  <joint name="ll1_ct" type="continuous">
    <parent link="ll1_coxa"/>
    <child link="ll1_femur"/>
    <origin xyz="0 0.14 0"/>
    <axis xyz="1 0 0"/>
    <calibration rising="0.0"/>
    <dynamics damping="0" friction="0"/>
  </joint>
  <transmission name="tran_ll1_ct">
    <type>transmission_interface/SimpleTransmission</type>
    <joint name="ll1_ct">
      <hardwareInterface>hardware_interface/EffortJointInterface</hardwareInterface>
    </joint>
    <actuator name="motor_ll1_ct">
      <hardwareInterface>hardware_interface/EffortJointInterface</hardwareInterface>
      <mechanicalReduction>1</mechanicalReduction>
    </actuator>
  </transmission>
  <joint name="ll1_ft" type="continuous">
    <parent link="ll1_femur"/>
    <child link="ll1_tibia"/>
    <origin xyz="0 0.28 0"/>
    <axis xyz="1 0 0"/>
    <calibration rising="0.0"/>
    <dynamics damping="0" friction="0"/>
  </joint>
  <transmission name="tran_ll1_ft">
    <type>transmission_interface/SimpleTransmission</type>
    <joint name="ll1_ft">
      <hardwareInterface>hardware_interface/EffortJointInterface</hardwareInterface>
    </joint>
    <actuator name="motor_ll1_ft">
      <hardwareInterface>hardware_interface/EffortJointInterface</hardwareInterface>
      <mechanicalReduction>1</mechanicalReduction>
    </actuator>
  </transmission>
  <joint name="ll1_wh" type="continuous">
    <parent link="ll1_tibia"/>
    <child link="ll1_wheel"/>
    <origin xyz="0 0.14 0"/>
    <axis xyz="0 1 0"/>
    <calibration rising="0.0"/>
    <dynamics damping="0" friction="0"/>
  </joint>
  <transmission name="tran_ll1_wh">
    <type>transmission_interface/SimpleTransmission</type>
    <joint name="ll1_wh">
      <hardwareInterface>hardware_interface/EffortJointInterface</hardwareInterface>
    </joint>
    <actuator name="motor_ll1_wh">
      <hardwareInterface>hardware_interface/EffortJointInterface</hardwareInterface>
      <mechanicalReduction>1</mechanicalReduction>
    </actuator>
  </transmission>
    
  <link name="lr2_coxa">
    <inertial>
      <origin rpy="1.57075 0 0" xyz="0 -0.07 0"/>
      <mass value="0.5"/>
      <inertia ixx="0.0012666666666666668" ixy="0" ixz="0" iyy="0.0012666666666666668" iyz="0" izz="0.0009"/>
    </inertial>
    <visual>
      <origin rpy="1.57075 0 0" xyz="0 -0.07 0"/>
      <geometry>
        <cylinder length="0.14" radius="0.06"/>
      </geometry>
      <material name="lr2_coxa_material">
        <color rgba="0 0.0 1.0 1.0"/>
      </material>
    </visual>
    <collision>
      <origin rpy="1.57075 0 0" xyz="0 -0.07 0"/>
      <geometry>
        <cylinder length="0.14" radius="0.06"/>
      </geometry>
    </collision>
  </link>
  <link name="lr2_femur">
    <inertial>
      <origin rpy="1.57075 0 0" xyz="0 -0.14 0"/>
      <mass value="3.0"/>
      <inertia ixx="0.022300000000000004" ixy="0" ixz="0" iyy="0.022300000000000004" iyz="0" izz="0.005399999999999999"/>
    </inertial>
    <visual>
      <origin rpy="1.57075 0 0" xyz="0 -0.14 0"/>
      <geometry>
        <cylinder length="0.28" radius="0.06"/>
      </geometry>
      <material name="lr2_femur_material">
        <color rgba="0 0.0 0.8 1.0"/>
      </material>
    </visual>
    <collision>
      <origin rpy="1.57075 0 0" xyz="0 -0.14 0"/>
      <geometry>
        <cylinder length="0.28" radius="0.06"/>
      </geometry>
    </collision>
  </link>
  <link name="lr2_tibia">
    <inertial>
      <origin rpy="1.57075 0 0" xyz="0 -0.07 0"/>
      <mass value="0.5"/>
      <inertia ixx="0.0012666666666666668" ixy="0" ixz="0" iyy="0.0012666666666666668" iyz="0" izz="0.0009"/>
    </inertial>
    <visual>
      <origin rpy="1.57075 0 0" xyz="0 -0.07 0"/>
      <geometry>
        <cylinder length="0.14" radius="0.06"/>
      </geometry>
      <material name="lr2_tibia_material">
        <color rgba="0 0.0 0.6 1.0"/>
      </material>
    </visual>
    <collision>
      <origin rpy="1.57075 0 0" xyz="0 -0.07 0"/>
      <geometry>
        <cylinder length="0.14" radius="0.06"/>
      </geometry>
    </collision>
  </link>
  <link name="lr2_wheel">
    <inertial>
      <origin rpy="1.57075 0 0" xyz="0 -0.05 0"/>
      <mass value="0.3"/>
      <inertia ixx="0.004046875" ixy="0" ixz="0" iyy="0.004046875" iyz="0" izz="0.007593750000000001"/>
    </inertial>
    <visual>
      <origin rpy="1.57075 0 0" xyz="0 -0.05 0"/>
      <geometry>
        <cylinder length="0.1" radius="0.125"/>
      </geometry>
      <material name="lr2_wheel_material">
        <color rgba="0 0.5 1.0 1.0"/>
      </material>
    </visual>
    <collision>
      <origin rpy="1.57075 0 0" xyz="0 -0.05 0"/>
      <geometry>
        <cylinder length="0.1" radius="0.125"/>
      </geometry>
    </collision>
  </link>
  <joint name="lr2_tc" type="continuous">
    <parent link="Body1"/>
    <child link="lr2_coxa"/>
    <origin xyz="0.39 -0.115 0"/>
    <axis xyz="0 1 0"/>
    <calibration rising="0.0"/>
    <dynamics damping="0" friction="0"/>
  </joint>
  <transmission name="tran_lr2_tc">
    <type>transmission_interface/SimpleTransmission</type>
    <joint name="lr2_tc">
      <hardwareInterface>hardware_interface/EffortJointInterface</hardwareInterface>
    </joint>
    <actuator name="motor_lr2_tc">
      <hardwareInterface>hardware_interface/EffortJointInterface</hardwareInterface>
      <mechanicalReduction>1</mechanicalReduction>
    </actuator>
  </transmission>
  <joint name="lr2_ct" type="continuous">
    <parent link="lr2_coxa"/>
    <child link="lr2_femur"/>
    <origin xyz="0 -0.14 0"/>
    <axis xyz="1 0 0"/>
    <calibration rising="0.0"/>
    <dynamics damping="0" friction="0"/>
  </joint>
  <transmission name="tran_lr2_ct">
    <type>transmission_interface/SimpleTransmission</type>
    <joint name="lr2_ct">
      <hardwareInterface>hardware_interface/EffortJointInterface</hardwareInterface>
    </joint>
    <actuator name="motor_lr2_ct">
      <hardwareInterface>hardware_interface/EffortJointInterface</hardwareInterface>
      <mechanicalReduction>1</mechanicalReduction>
    </actuator>
  </transmission>
  <joint name="lr2_ft" type="continuous">
    <parent link="lr2_femur"/>
    <child link="lr2_tibia"/>
    <origin xyz="0 -0.28 0"/>
    <axis xyz="1 0 0"/>
    <calibration rising="0.0"/>
    <dynamics damping="0" friction="0"/>
  </joint>
  <transmission name="tran_lr2_ft">
    <type>transmission_interface/SimpleTransmission</type>
    <joint name="lr2_ft">
      <hardwareInterface>hardware_interface/EffortJointInterface</hardwareInterface>
    </joint>
    <actuator name="motor_lr2_ft">
      <hardwareInterface>hardware_interface/EffortJointInterface</hardwareInterface>
      <mechanicalReduction>1</mechanicalReduction>
    </actuator>
  </transmission>
  <joint name="lr2_wh" type="continuous">
    <parent link="lr2_tibia"/>
    <child link="lr2_wheel"/>
    <origin xyz="0 -0.14 0"/>
    <axis xyz="0 1 0"/>
    <calibration rising="0.0"/>
    <dynamics damping="0" friction="0"/>
  </joint>
  <transmission name="tran_lr2_wh">
    <type>transmission_interface/SimpleTransmission</type>
    <joint name="lr2_wh">
      <hardwareInterface>hardware_interface/EffortJointInterface</hardwareInterface>
    </joint>
    <actuator name="motor_lr2_wh">
      <hardwareInterface>hardware_interface/EffortJointInterface</hardwareInterface>
      <mechanicalReduction>1</mechanicalReduction>
    </actuator>
  </transmission>

  <link name="ll2_coxa">
    <inertial>
      <origin rpy="-1.57075 0 0" xyz="0 0.07 0"/>
      <mass value="0.5"/>
      <inertia ixx="0.0012666666666666668" ixy="0" ixz="0" iyy="0.0012666666666666668" iyz="0" izz="0.0009"/>
    </inertial>
    <visual>
      <origin rpy="-1.57075 0 0" xyz="0 0.07 0"/>
      <geometry>
        <cylinder length="0.14" radius="0.06"/>
      </geometry>
      <material name="ll2_coxa_material">
        <color rgba="0 0.0 1.0 1.0"/>
      </material>
    </visual>
    <collision>
      <origin rpy="-1.57075 0 0" xyz="0 0.07 0"/>
      <geometry>
        <cylinder length="0.14" radius="0.06"/>
      </geometry>
    </collision>
  </link>
  <link name="ll2_femur">
    <inertial>
      <origin rpy="-1.57075 0 0" xyz="0 0.14 0"/>
      <mass value="3.0"/>
      <inertia ixx="0.022300000000000004" ixy="0" ixz="0" iyy="0.022300000000000004" iyz="0" izz="0.005399999999999999"/>
    </inertial>
    <visual>
      <origin rpy="-1.57075 0 0" xyz="0 0.14 0"/>
      <geometry>
        <cylinder length="0.28" radius="0.06"/>
      </geometry>
      <material name="ll2_femur_material">
        <color rgba="0 0.0 0.8 1.0"/>
      </material>
    </visual>
    <collision>
      <origin rpy="-1.57075 0 0" xyz="0 0.14 0"/>
      <geometry>
        <cylinder length="0.28" radius="0.06"/>
      </geometry>
    </collision>
  </link>
  <link name="ll2_tibia">
    <inertial>
      <origin rpy="-1.57075 0 0" xyz="0 0.07 0"/>
      <mass value="0.5"/>
      <inertia ixx="0.0012666666666666668" ixy="0" ixz="0" iyy="0.0012666666666666668" iyz="0" izz="0.0009"/>
    </inertial>
    <visual>
      <origin rpy="-1.57075 0 0" xyz="0 0.07 0"/>
      <geometry>
        <cylinder length="0.14" radius="0.06"/>
      </geometry>
      <material name="ll2_tibia_material">
        <color rgba="0 0.0 0.6 1.0"/>
      </material>
    </visual>
    <collision>
      <origin rpy="-1.57075 0 0" xyz="0 0.07 0"/>
      <geometry>
        <cylinder length="0.14" radius="0.06"/>
      </geometry>
    </collision>
  </link>
  <link name="ll2_wheel">
    <inertial>
      <origin rpy="-1.57075 0 0" xyz="0 0.05 0"/>
      <mass value="0.3"/>
      <inertia ixx="0.004046875" ixy="0" ixz="0" iyy="0.004046875" iyz="0" izz="0.007593750000000001"/>
    </inertial>
    <visual>
      <origin rpy="-1.57075 0 0" xyz="0 0.05 0"/>
      <geometry>
        <cylinder length="0.1" radius="0.125"/>
      </geometry>
      <material name="ll2_wheel_material">
        <color rgba="0 0.5 1.0 1.0"/>
      </material>
    </visual>
    <collision>
      <origin rpy="-1.57075 0 0" xyz="0 0.05 0"/>
      <geometry>
        <cylinder length="0.1" radius="0.125"/>
      </geometry>
    </collision>
  </link>

  <joint name="ll2_tc" type="continuous">
    <parent link="Body1"/>
    <child link="ll2_coxa"/>
    <origin xyz="0.39 0.115 0"/>
    <axis xyz="0 1 0"/>
    <calibration rising="0.0"/>
    <dynamics damping="0" friction="0"/>
  </joint>
  <transmission name="tran_ll2_tc">
    <type>transmission_interface/SimpleTransmission</type>
    <joint name="ll2_tc">
      <hardwareInterface>hardware_interface/EffortJointInterface</hardwareInterface>
    </joint>
    <actuator name="motor_ll2_tc">
      <hardwareInterface>hardware_interface/EffortJointInterface</hardwareInterface>
      <mechanicalReduction>1</mechanicalReduction>
    </actuator>
  </transmission>
  <joint name="ll2_ct" type="continuous">
    <parent link="ll2_coxa"/>
    <child link="ll2_femur"/>
    <origin xyz="0 0.14 0"/>
    <axis xyz="1 0 0"/>
    <calibration rising="0.0"/>
    <dynamics damping="0" friction="0"/>
  </joint>
  <transmission name="tran_ll2_ct">
    <type>transmission_interface/SimpleTransmission</type>
    <joint name="ll2_ct">
      <hardwareInterface>hardware_interface/EffortJointInterface</hardwareInterface>
    </joint>
    <actuator name="motor_ll2_ct">
      <hardwareInterface>hardware_interface/EffortJointInterface</hardwareInterface>
      <mechanicalReduction>1</mechanicalReduction>
    </actuator>
  </transmission>
  <joint name="ll2_ft" type="continuous">
    <parent link="ll2_femur"/>
    <child link="ll2_tibia"/>
    <origin xyz="0 0.28 0"/>
    <axis xyz="1 0 0"/>
    <calibration rising="0.0"/>
    <dynamics damping="0" friction="0"/>
  </joint>
  <transmission name="tran_ll2_ft">
    <type>transmission_interface/SimpleTransmission</type>
    <joint name="ll2_ft">
      <hardwareInterface>hardware_interface/EffortJointInterface</hardwareInterface>
    </joint>
    <actuator name="motor_ll2_ft">
      <hardwareInterface>hardware_interface/EffortJointInterface</hardwareInterface>
      <mechanicalReduction>1</mechanicalReduction>
    </actuator>
  </transmission>
  <joint name="ll2_wh" type="continuous">
    <parent link="ll2_tibia"/>
    <child link="ll2_wheel"/>
    <origin xyz="0 0.14 0"/>
    <axis xyz="0 1 0"/>
    <calibration rising="0.0"/>
    <dynamics damping="0" friction="0"/>
  </joint>
  <transmission name="tran_ll2_wh">
    <type>transmission_interface/SimpleTransmission</type>
    <joint name="ll2_wh">
      <hardwareInterface>hardware_interface/EffortJointInterface</hardwareInterface>
    </joint>
    <actuator name="motor_ll2_wh">
      <hardwareInterface>hardware_interface/EffortJointInterface</hardwareInterface>
      <mechanicalReduction>1</mechanicalReduction>
    </actuator>
  </transmission>

  <link name="lr3_coxa">
    <inertial>
      <origin rpy="1.57075 0 0" xyz="0 -0.07 0"/>
      <mass value="0.5"/>
      <inertia ixx="0.0012666666666666668" ixy="0" ixz="0" iyy="0.0012666666666666668" iyz="0" izz="0.0009"/>
    </inertial>
    <visual>
      <origin rpy="1.57075 0 0" xyz="0 -0.07 0"/>
      <geometry>
        <cylinder length="0.14" radius="0.06"/>
      </geometry>
      <material name="lr3_coxa_material">
        <color rgba="0 0.0 1.0 1.0"/>
      </material>
    </visual>
    <collision>
      <origin rpy="1.57075 0 0" xyz="0 -0.07 0"/>
      <geometry>
        <cylinder length="0.14" radius="0.06"/>
      </geometry>
    </collision>
  </link>
  <link name="lr3_femur">
    <inertial>
      <origin rpy="1.57075 0 0" xyz="0 -0.14 0"/>
      <mass value="3.0"/>
      <inertia ixx="0.022300000000000004" ixy="0" ixz="0" iyy="0.022300000000000004" iyz="0" izz="0.005399999999999999"/>
    </inertial>
    <visual>
      <origin rpy="1.57075 0 0" xyz="0 -0.14 0"/>
      <geometry>
        <cylinder length="0.28" radius="0.06"/>
      </geometry>
      <material name="lr3_femur_material">
        <color rgba="0 0.0 0.8 1.0"/>
      </material>
    </visual>
    <collision>
      <origin rpy="1.57075 0 0" xyz="0 -0.14 0"/>
      <geometry>
        <cylinder length="0.28" radius="0.06"/>
      </geometry>
    </collision>
  </link>
  <link name="lr3_tibia">
     <inertial>
      <origin rpy="1.57075 0 0" xyz="0 -0.07 0"/>
      <mass value="0.5"/>
      <inertia ixx="0.0012666666666666668" ixy="0" ixz="0" iyy="0.0012666666666666668" iyz="0" izz="0.0009"/>
    </inertial>
    <visual>
      <origin rpy="1.57075 0 0" xyz="0 -0.07 0"/>
      <geometry>
        <cylinder length="0.14" radius="0.06"/>
      </geometry>
      <material name="lr3_tibia_material">
        <color rgba="0 0.0 0.6 1.0"/>
      </material>
    </visual>
    <collision>
      <origin rpy="1.57075 0 0" xyz="0 -0.07 0"/>
      <geometry>
        <cylinder length="0.14" radius="0.06"/>
      </geometry>
    </collision>
  </link>
  <link name="lr3_wheel">
    <inertial>
      <origin rpy="1.57075 0 0" xyz="0 -0.05 0"/>
      <mass value="0.3"/>
      <inertia ixx="0.004046875" ixy="0" ixz="0" iyy="0.004046875" iyz="0" izz="0.007593750000000001"/>
    </inertial>
    <visual>
      <origin rpy="1.57075 0 0" xyz="0 -0.05 0"/>
      <geometry>
        <cylinder length="0.1" radius="0.125"/>
      </geometry>
      <material name="lr3_wheel_material">
        <color rgba="0 0.5 1.0 1.0"/>
      </material>
    </visual>
    <collision>
      <origin rpy="1.57075 0 0" xyz="0 -0.05 0"/>
      <geometry>
        <cylinder length="0.1" radius="0.125"/>
      </geometry>
    </collision>
  </link>

  <joint name="lr3_tc" type="continuous">
    <parent link="Body1"/>
    <child link="lr3_coxa"/>
    <origin xyz="0.11 -0.115 0"/>
    <axis xyz="0 1 0"/>
    <calibration rising="0.0"/>
    <dynamics damping="0" friction="0"/>
  </joint>
  <transmission name="tran_lr3_tc">
    <type>transmission_interface/SimpleTransmission</type>
    <joint name="lr3_tc">
      <hardwareInterface>hardware_interface/EffortJointInterface</hardwareInterface>
    </joint>
    <actuator name="motor_lr3_tc">
      <hardwareInterface>hardware_interface/EffortJointInterface</hardwareInterface>
      <mechanicalReduction>1</mechanicalReduction>
    </actuator>
  </transmission>
  <joint name="lr3_ct" type="continuous">
    <parent link="lr3_coxa"/>
    <child link="lr3_femur"/>
    <origin xyz="0 -0.14 0"/>
    <axis xyz="1 0 0"/>
    <calibration rising="0.0"/>
    <dynamics damping="0" friction="0"/>
  </joint>
  <transmission name="tran_lr3_ct">
    <type>transmission_interface/SimpleTransmission</type>
    <joint name="lr3_ct">
      <hardwareInterface>hardware_interface/EffortJointInterface</hardwareInterface>
    </joint>
    <actuator name="motor_lr3_ct">
      <hardwareInterface>hardware_interface/EffortJointInterface</hardwareInterface>
      <mechanicalReduction>1</mechanicalReduction>
    </actuator>
  </transmission>
  <joint name="lr3_ft" type="continuous">
    <parent link="lr3_femur"/>
    <child link="lr3_tibia"/>
    <origin xyz="0 -0.28 0"/>
    <axis xyz="1 0 0"/>
    <calibration rising="0.0"/>
    <dynamics damping="0" friction="0"/>
  </joint>
  <transmission name="tran_lr3_ft">
    <type>transmission_interface/SimpleTransmission</type>
    <joint name="lr3_ft">
      <hardwareInterface>hardware_interface/EffortJointInterface</hardwareInterface>
    </joint>
    <actuator name="motor_lr3_ft">
      <hardwareInterface>hardware_interface/EffortJointInterface</hardwareInterface>
      <mechanicalReduction>1</mechanicalReduction>
    </actuator>
  </transmission>
  <joint name="lr3_wh" type="continuous">
    <parent link="lr3_tibia"/>
    <child link="lr3_wheel"/>
    <origin xyz="0 -0.14 0"/>
    <axis xyz="0 1 0"/>
    <calibration rising="0.0"/>
    <dynamics damping="0" friction="0"/>
  </joint>
  <transmission name="tran_lr3_wh">
    <type>transmission_interface/SimpleTransmission</type>
    <joint name="lr3_wh">
      <hardwareInterface>hardware_interface/EffortJointInterface</hardwareInterface>
    </joint>
    <actuator name="motor_lr3_wh">
      <hardwareInterface>hardware_interface/EffortJointInterface</hardwareInterface>
      <mechanicalReduction>1</mechanicalReduction>
    </actuator>
  </transmission>

  <link name="ll3_coxa">
    <inertial>
      <origin rpy="-1.57075 0 0" xyz="0 0.07 0"/>
      <mass value="0.5"/>
      <inertia ixx="0.0012666666666666668" ixy="0" ixz="0" iyy="0.0012666666666666668" iyz="0" izz="0.0009"/>
    </inertial>
    <visual>
      <origin rpy="-1.57075 0 0" xyz="0 0.07 0"/>
      <geometry>
        <cylinder length="0.14" radius="0.06"/>
      </geometry>
      <material name="ll3_coxa_material">
        <color rgba="0 0.0 1.0 1.0"/>
      </material>
    </visual>
    <collision>
      <origin rpy="-1.57075 0 0" xyz="0 0.07 0"/>
      <geometry>
        <cylinder length="0.14" radius="0.06"/>
      </geometry>
    </collision>
  </link>
  <link name="ll3_femur">
    <inertial>
      <origin rpy="-1.57075 0 0" xyz="0 0.14 0"/>
      <mass value="3.0"/>
      <inertia ixx="0.022300000000000004" ixy="0" ixz="0" iyy="0.022300000000000004" iyz="0" izz="0.005399999999999999"/>
    </inertial>
    <visual>
      <origin rpy="-1.57075 0 0" xyz="0 0.14 0"/>
      <geometry>
        <cylinder length="0.28" radius="0.06"/>
      </geometry>
      <material name="ll3_femur_material">
        <color rgba="0 0.0 0.8 1.0"/>
      </material>
    </visual>
    <collision>
      <origin rpy="-1.57075 0 0" xyz="0 0.14 0"/>
      <geometry>
        <cylinder length="0.28" radius="0.06"/>
      </geometry>
    </collision>
  </link>
  <link name="ll3_tibia">
    <inertial>
      <origin rpy="-1.57075 0 0" xyz="0 0.07 0"/>
      <mass value="0.5"/>
      <inertia ixx="0.0012666666666666668" ixy="0" ixz="0" iyy="0.0012666666666666668" iyz="0" izz="0.0009"/>
    </inertial>
    <visual>
      <origin rpy="-1.57075 0 0" xyz="0 0.07 0"/>
      <geometry>
        <cylinder length="0.14" radius="0.06"/>
      </geometry>
      <material name="ll3_tibia_material">
        <color rgba="0 0.0 0.6 1.0"/>
      </material>
    </visual>
    <collision>
      <origin rpy="-1.57075 0 0" xyz="0 0.07 0"/>
      <geometry>
        <cylinder length="0.14" radius="0.06"/>
      </geometry>
    </collision>
  </link>
   <link name="ll3_wheel">
    <inertial>
      <origin rpy="-1.57075 0 0" xyz="0 0.05 0"/>
      <mass value="0.3"/>
      <inertia ixx="0.004046875" ixy="0" ixz="0" iyy="0.004046875" iyz="0" izz="0.007593750000000001"/>
    </inertial>
    <visual>
      <origin rpy="-1.57075 0 0" xyz="0 0.05 0"/>
      <geometry>
        <cylinder length="0.1" radius="0.125"/>
      </geometry>
      <material name="ll3_wheel_material">
        <color rgba="0 0.5 1.0 1.0"/>
      </material>
    </visual>
    <collision>
      <origin rpy="-1.57075 0 0" xyz="0 0.05 0"/>
      <geometry>
        <cylinder length="0.1" radius="0.125"/>
      </geometry>
    </collision>
  </link>

  <joint name="ll3_tc" type="continuous">
    <parent link="Body1"/>
    <child link="ll3_coxa"/>
    <origin xyz="0.11 0.115 0"/>
    <axis xyz="0 1 0"/>
    <calibration rising="0.0"/>
    <dynamics damping="0" friction="0"/>
  </joint>
  <transmission name="tran_ll3_tc">
    <type>transmission_interface/SimpleTransmission</type>
    <joint name="ll3_tc">
      <hardwareInterface>hardware_interface/EffortJointInterface</hardwareInterface>
    </joint>
    <actuator name="motor_ll3_tc">
      <hardwareInterface>hardware_interface/EffortJointInterface</hardwareInterface>
      <mechanicalReduction>1</mechanicalReduction>
    </actuator>
  </transmission>
  <joint name="ll3_ct" type="continuous">
    <parent link="ll3_coxa"/>
    <child link="ll3_femur"/>
    <origin xyz="0 0.14 0"/>
    <axis xyz="1 0 0"/>
    <calibration rising="0.0"/>
    <dynamics damping="0" friction="0"/>
  </joint>
  <transmission name="tran_ll3_ct">
    <type>transmission_interface/SimpleTransmission</type>
    <joint name="ll3_ct">
      <hardwareInterface>hardware_interface/EffortJointInterface</hardwareInterface>
    </joint>
    <actuator name="motor_ll3_ct">
      <hardwareInterface>hardware_interface/EffortJointInterface</hardwareInterface>
      <mechanicalReduction>1</mechanicalReduction>
    </actuator>
  </transmission>
  <joint name="ll3_ft" type="continuous">
    <parent link="ll3_femur"/>
    <child link="ll3_tibia"/>
    <origin xyz="0 0.28 0"/>
    <axis xyz="1 0 0"/>
    <calibration rising="0.0"/>
    <dynamics damping="0" friction="0"/>
  </joint>
  <transmission name="tran_ll3_ft">
    <type>transmission_interface/SimpleTransmission</type>
    <joint name="ll3_ft">
      <hardwareInterface>hardware_interface/EffortJointInterface</hardwareInterface>
    </joint>
    <actuator name="motor_ll3_ft">
      <hardwareInterface>hardware_interface/EffortJointInterface</hardwareInterface>
      <mechanicalReduction>1</mechanicalReduction>
    </actuator>
  </transmission>
  <joint name="ll3_wh" type="continuous">
    <parent link="ll3_tibia"/>
    <child link="ll3_wheel"/>
    <origin xyz="0 0.14 0"/>
    <axis xyz="0 1 0"/>
    <calibration rising="0.0"/>
    <dynamics damping="0" friction="0"/>
  </joint>
  <transmission name="tran_ll3_wh">
    <type>transmission_interface/SimpleTransmission</type>
    <joint name="ll3_wh">
      <hardwareInterface>hardware_interface/EffortJointInterface</hardwareInterface>
    </joint>
    <actuator name="motor_ll3_wh">
      <hardwareInterface>hardware_interface/EffortJointInterface</hardwareInterface>
      <mechanicalReduction>1</mechanicalReduction>
    </actuator>
  </transmission>  <!--
    <xacro:make_right_leg name = "LR1" body = "Body1"  legOrigin="${body_x/2} ${-body_y / 2} 0" coxaLength= "${coxa_l}" coxaMass="${coxa_m}" femurLength="${femur_l}" femurMass="${femur_m}" tibiaLength="${tibia_l}" tibiaMass="${tibia_m}" 
        toeMass="${toe_m}" radius="${radius}" damping="0" friction="0" collision="LR1_tibia_fixed_joint_lump__LR1_toe_collision_collision_1" />
    <xacro:make_left_leg name = "LL1" body = "Body1"  legOrigin="${body_x/2} ${body_y / 2} 0" coxaLength="${coxa_l}" coxaMass="${coxa_m}" femurLength="${femur_l}" femurMass="${femur_m}" tibiaLength="${tibia_l}" tibiaMass="${tibia_m}" 
        toeMass="${toe_m}" radius="${radius}" damping="0" friction="0" collision="LL1_tibia_fixed_joint_lump__LL1_toe_collision_collision_1" />
    <xacro:make_right_leg name = "LR2" body = "Body2"  legOrigin="${body_x/2} ${-body_y / 2} 0" coxaLength= "${coxa_l}" coxaMass="${coxa_m}" femurLength="${femur_l}" femurMass="${femur_m}" tibiaLength="${tibia_l}" tibiaMass="${tibia_m}" 
        toeMass="${toe_m}" radius="${radius}" damping="0" friction="0" collision="LR2_tibia_fixed_joint_lump__LR2_toe_collision_collision_1" />
    <xacro:make_left_leg name = "LL2" body = "Body2"  legOrigin="${body_x/2} ${body_y / 2} 0" coxaLength="${coxa_l}" coxaMass="${coxa_m}" femurLength="${femur_l}" femurMass="${femur_m}" tibiaLength="${tibia_l}" tibiaMass="${tibia_m}" 
        toeMass="${toe_m}" radius="${radius}" damping="0" friction="0" collision="LL2_tibia_fixed_joint_lump__LL2_toe_collision_collision_1" />
    <xacro:make_right_leg name = "LR3" body = "Body3"  legOrigin="${body_x/2} ${-body_y / 2} 0" coxaLength= "${coxa_l}" coxaMass="${coxa_m}" femurLength="${femur_l}" femurMass="${femur_m}" tibiaLength="${tibia_l}" tibiaMass="${tibia_m}" 
        toeMass="${toe_m}" radius="${radius}" damping="0" friction="0" collision="LR3_tibia_fixed_joint_lump__LR3_toe_collision_collision_1" />
    <xacro:make_left_leg name = "LL3" body = "Body3"  legOrigin="${body_x/2} ${body_y / 2} 0" coxaLength="${coxa_l}" coxaMass="${coxa_m}" femurLength="${femur_l}" femurMass="${femur_m}" tibiaLength="${tibia_l}" tibiaMass="${tibia_m}" 
        toeMass="${toe_m}" radius="${radius}" damping="0" friction="0"  collision="LL3_tibia_fixed_joint_lump__LL3_toe_collision_collision_1"/>
    <xacro:make_right_leg name = "LR4" body = "Body4"  legOrigin="${body_x/2} ${-body_y / 2} 0" coxaLength= "${coxa_l}" coxaMass="${coxa_m}" femurLength="${femur_l}" femurMass="${femur_m}" tibiaLength="${tibia_l}" tibiaMass="${tibia_m}" 
        toeMass="${toe_m}" radius="${radius}" damping="0" friction="0" collision="LR4_tibia_fixed_joint_lump__LR4_toe_collision_collision_1"/>
    <xacro:make_left_leg name = "LL4" body = "Body4"  legOrigin="${body_x/2} ${body_y / 2} 0" coxaLength="${coxa_l}" coxaMass="${coxa_m}" femurLength="${femur_l}" femurMass="${femur_m}" tibiaLength="${tibia_l}" tibiaMass="${tibia_m}" 
        toeMass="${toe_m}" radius="${radius}" damping="0" friction="0" collision="LL4_tibia_fixed_joint_lump__LL4_toe_collision_collision_1"/>
    -->
 <gazebo reference="lr0_wheel">
    <material>Gazebo/Red</material>
    <selfCollide>true</selfCollide>
    <mu1> 0.1 </mu1>
    <mu2> 0.1 </mu2>
    <maxVel> 1.0 </maxVel>
    <minDepth>0.001</minDepth>
    <kp>50.0</kp>
    <kd>1.0</kd>
  </gazebo>
  <gazebo reference="lr1_wheel">
    <material>Gazebo/Red</material>
    <selfCollide>true</selfCollide>
    <mu1> 0.1 </mu1>
    <mu2> 0.1 </mu2>
    <maxVel> 1.0 </maxVel>
    <minDepth>0.001</minDepth>
    <kp>50.0</kp>
    <kd>1.0</kd>
  </gazebo>
 <gazebo reference="lr2_wheel">
    <material>Gazebo/Red</material>
    <selfCollide>true</selfCollide>
    <mu1> 0.1 </mu1>
    <mu2> 0.1 </mu2>
    <maxVel> 1.0 </maxVel>
    <minDepth>0.001</minDepth>
    <kp>50.0</kp>
    <kd>1.0</kd>
  </gazebo>
  <gazebo reference="lr3_wheel">
    <material>Gazebo/Red</material>
    <selfCollide>true</selfCollide>
    <mu1> 0.1 </mu1>
    <mu2> 0.1 </mu2>
    <maxVel> 1.0 </maxVel>
    <minDepth>0.001</minDepth>
    <kp>50.0</kp>
    <kd>1.0</kd>
  </gazebo>
 
 <gazebo reference="ll0_wheel">
    <material>Gazebo/Red</material>
    <selfCollide>true</selfCollide>
    <mu1> 0.1 </mu1>
    <mu2> 0.1 </mu2>
    <maxVel> 1.0 </maxVel>
    <minDepth>0.001</minDepth>
    <kp>50.0</kp>
    <kd>1.0</kd>
  </gazebo>
  <gazebo reference="ll1_wheel">
    <material>Gazebo/Red</material>
    <selfCollide>true</selfCollide>
    <mu1> 0.1 </mu1>
    <mu2> 0.1 </mu2>
    <maxVel> 1.0 </maxVel>
    <minDepth>0.001</minDepth>
    <kp>50.0</kp>
    <kd>1.0</kd>
  </gazebo>
 <gazebo reference="ll2_wheel">
    <material>Gazebo/Red</material>
    <selfCollide>true</selfCollide>
    <mu1> 0.1 </mu1>
    <mu2> 0.1 </mu2>
    <maxVel> 1.0 </maxVel>
    <minDepth>0.001</minDepth>
    <kp>50.0</kp>
    <kd>1.0</kd>
  </gazebo>
  <gazebo reference="ll3_wheel">
    <material>Gazebo/Red</material>
    <selfCollide>true</selfCollide>
    <mu1> 0.1 </mu1>
    <mu2> 0.1 </mu2>
    <maxVel> 1.0 </maxVel>
    <minDepth>0.001</minDepth>
    <kp>50.0</kp>
    <kd>1.0</kd>
  </gazebo>

 
  <!-- ros_control plugin -->
   <!-- ros2_control plugin -->
<!-- ros2_control -->
  <ros2_control name="IgnitionSystem" type="system">
    <hardware>
      <plugin>ign_ros2_control/IgnitionSystem</plugin>
    </hardware>
    <joint name="torso">
      <command_interface name="effort">
        <param name="min">-100</param>
        <param name="max">100</param>
      </command_interface>
      <state_interface name="position"/>
      <state_interface name="velocity"/>
      <state_interface name="effort"/>
    </joint>
      <!-- Rev Link Right side -->
    <joint name="lr0_tc">
      <command_interface name="effort">
        <param name="min">-100</param>
        <param name="max">100</param>
      </command_interface>
      <state_interface name="position"/>
      <state_interface name="velocity"/>
      <state_interface name="effort"/>
    </joint>
    <joint name="lr0_ct">
      <command_interface name="effort">
        <param name="min">-100</param>
        <param name="max">100</param>
      </command_interface>
      <state_interface name="position"/>
      <state_interface name="velocity"/>
      <state_interface name="effort"/>
    </joint>
    <joint name="lr0_ft">
      <command_interface name="effort">
        <param name="min">-100</param>
        <param name="max">100</param>
      </command_interface>
      <state_interface name="position"/>
      <state_interface name="velocity"/>
      <state_interface name="effort"/>
    </joint>
    <joint name="lr0_wh">
      <command_interface name="effort">
        <param name="min">-100</param>
        <param name="max">100</param>
      </command_interface>
      <state_interface name="position"/>
      <state_interface name="velocity"/>
      <state_interface name="effort"/>
    </joint>

    <joint name="lr1_tc">
      <command_interface name="effort">
        <param name="min">-100</param>
        <param name="max">100</param>
      </command_interface>
      <state_interface name="position"/>
      <state_interface name="velocity"/>
      <state_interface name="effort"/>
    </joint>
    <joint name="lr1_ct">
      <command_interface name="effort">
        <param name="min">-100</param>
        <param name="max">100</param>
      </command_interface>
      <state_interface name="position"/>
      <state_interface name="velocity"/>
      <state_interface name="effort"/>
    </joint>
    <joint name="lr1_ft">
      <command_interface name="effort">
        <param name="min">-100</param>
        <param name="max">100</param>
      </command_interface>
      <state_interface name="position"/>
      <state_interface name="velocity"/>
      <state_interface name="effort"/>
    </joint>
    <joint name="lr1_wh">
      <command_interface name="effort">
        <param name="min">-100</param>
        <param name="max">100</param>
      </command_interface>
      <state_interface name="position"/>
      <state_interface name="velocity"/>
      <state_interface name="effort"/>
    </joint>

    <joint name="lr2_tc">
      <command_interface name="effort">
        <param name="min">-100</param>
        <param name="max">100</param>
      </command_interface>
      <state_interface name="position"/>
      <state_interface name="velocity"/>
      <state_interface name="effort"/>
    </joint>
    <joint name="lr2_ct">
      <command_interface name="effort">
        <param name="min">-100</param>
        <param name="max">100</param>
      </command_interface>
      <state_interface name="position"/>
      <state_interface name="velocity"/>
      <state_interface name="effort"/>
    </joint>
    <joint name="lr2_ft">
      <command_interface name="effort">
        <param name="min">-100</param>
        <param name="max">100</param>
      </command_interface>
      <state_interface name="position"/>
      <state_interface name="velocity"/>
      <state_interface name="effort"/>
    </joint>
    <joint name="lr2_wh">
      <command_interface name="effort">
        <param name="min">-100</param>
        <param name="max">100</param>
      </command_interface>
      <state_interface name="position"/>
      <state_interface name="velocity"/>
      <state_interface name="effort"/>
    </joint>
    
    <joint name="lr3_tc">
      <command_interface name="effort">
        <param name="min">-100</param>
        <param name="max">100</param>
      </command_interface>
      <state_interface name="position"/>
      <state_interface name="velocity"/>
      <state_interface name="effort"/>
    </joint>
    <joint name="lr3_ct">
      <command_interface name="effort">
        <param name="min">-100</param>
        <param name="max">100</param>
      </command_interface>
      <state_interface name="position"/>
      <state_interface name="velocity"/>
      <state_interface name="effort"/>
    </joint>
    <joint name="lr3_ft">
      <command_interface name="effort">
        <param name="min">-100</param>
        <param name="max">100</param>
      </command_interface>
      <state_interface name="position"/>
      <state_interface name="velocity"/>
      <state_interface name="effort"/>
    </joint>
    <joint name="lr3_wh">
      <command_interface name="effort">
        <param name="min">-100</param>
        <param name="max">100</param>
      </command_interface>
      <state_interface name="position"/>
      <state_interface name="velocity"/>
      <state_interface name="effort"/>
    </joint>

     <!-- Rev Link Left side -->
    <joint name="ll0_tc">
      <command_interface name="effort">
        <param name="min">-100</param>
        <param name="max">100</param>
      </command_interface>
      <state_interface name="position"/>
      <state_interface name="velocity"/>
      <state_interface name="effort"/>
    </joint>
    <joint name="ll0_ct">
      <command_interface name="effort">
        <param name="min">-100</param>
        <param name="max">100</param>
      </command_interface>
      <state_interface name="position"/>
      <state_interface name="velocity"/>
      <state_interface name="effort"/>
    </joint>
    <joint name="ll0_ft">
      <command_interface name="effort">
        <param name="min">-100</param>
        <param name="max">100</param>
      </command_interface>
      <state_interface name="position"/>
      <state_interface name="velocity"/>
      <state_interface name="effort"/>
    </joint>
    <joint name="ll0_wh">
      <command_interface name="effort">
        <param name="min">-100</param>
        <param name="max">100</param>
      </command_interface>
      <state_interface name="position"/>
      <state_interface name="velocity"/>
      <state_interface name="effort"/>
    </joint>
    
    <joint name="ll1_tc">
      <command_interface name="effort">
        <param name="min">-100</param>
        <param name="max">100</param>
      </command_interface>
      <state_interface name="position"/>
      <state_interface name="velocity"/>
      <state_interface name="effort"/>
    </joint>
    <joint name="ll1_ct">
      <command_interface name="effort">
        <param name="min">-100</param>
        <param name="max">100</param>
      </command_interface>
      <state_interface name="position"/>
      <state_interface name="velocity"/>
      <state_interface name="effort"/>
    </joint>
    <joint name="ll1_ft">
      <command_interface name="effort">
        <param name="min">-100</param>
        <param name="max">100</param>
      </command_interface>
      <state_interface name="position"/>
      <state_interface name="velocity"/>
      <state_interface name="effort"/>
    </joint>
    <joint name="ll1_wh">
      <command_interface name="effort">
        <param name="min">-100</param>
        <param name="max">100</param>
      </command_interface>
      <state_interface name="position"/>
      <state_interface name="velocity"/>
      <state_interface name="effort"/>
    </joint>

    <joint name="ll2_tc">
      <command_interface name="effort">
        <param name="min">-100</param>
        <param name="max">100</param>
      </command_interface>
      <state_interface name="position"/>
      <state_interface name="velocity"/>
      <state_interface name="effort"/>
    </joint>
    <joint name="ll2_ct">
      <command_interface name="effort">
        <param name="min">-100</param>
        <param name="max">100</param>
      </command_interface>
      <state_interface name="position"/>
      <state_interface name="velocity"/>
      <state_interface name="effort"/>
    </joint>
    <joint name="ll2_ft">
      <command_interface name="effort">
        <param name="min">-100</param>
        <param name="max">100</param>
      </command_interface>
      <state_interface name="position"/>
      <state_interface name="velocity"/>
      <state_interface name="effort"/>
    </joint>
    <joint name="ll2_wh">
      <command_interface name="effort">
        <param name="min">-100</param>
        <param name="max">100</param>
      </command_interface>
      <state_interface name="position"/>
      <state_interface name="velocity"/>
      <state_interface name="effort"/>
    </joint>
    
    <joint name="ll3_tc">
      <command_interface name="effort">
        <param name="min">-100</param>
        <param name="max">100</param>
      </command_interface>msg
      <state_interface name="position"/>
      <state_interface name="velocity"/>
      <state_interface name="effort"/>
    </joint>
    <joint name="ll3_ct">
      <command_interface name="effort">
        <param name="min">-100</param>
        <param name="max">100</param>
      </command_interface>
      <state_interface name="position"/>
      <state_interface name="velocity"/>
      <state_interface name="effort"/>
    </joint>
    <joint name="ll3_ft">
      <command_interface name="effort">
        <param name="min">-100</param>
        <param name="max">100</param>
      </command_interface>
      <state_interface name="position"/>
      <state_interface name="velocity"/>
      <state_interface name="effort"/>
    </joint>
    <joint name="ll3_wh">
      <command_interface name="effort">
        <param name="min">-100</param>
        <param name="max">100</param>
      </command_interface>
      <state_interface name="position"/>
      <state_interface name="velocity"/>
      <state_interface name="effort"/>
    </joint>

  </ros2_control>

  <!-- ros2_control -->
  <gazebo>
    <!-- <plugin filename="libgazebo_ros2_control.so" name="gazebo_ros2_control"> -->
    <plugin name="ign_ros2_control::IgnitionROS2ControlPlugin" filename="ign_ros2_control-system">     <!-- <robot_param>robot_description</robot_param> -->
     <!-- <robot_param_node>robot_state_publisher</robot_param_node> -->
      <!-- <parameters>$(find manta_v2_gazebo_ros2_control)/config/manta_v2_moveit_controller.yaml</parameters> -->
     <parameters>$(find robot_gazebo_ros2_control)/config/robot_trajectory_controller_8wheel.yaml</parameters>  
      <!--<parameters>$(find robot_gazebo_ros2_control)/config/robot_effort_controller.yaml</parameters> -->
     <controller_manager_prefix_node_name>controller_manager</controller_manager_prefix_node_name>
    </plugin>


    <!-- Global odometer -->
    <plugin
      filename="ignition-gazebo-odometry-publisher-system"
      name="ignition::gazebo::systems::OdometryPublisher">
      <odom_publish_frequency>50</odom_publish_frequency>
      <odom_topic>/odom</odom_topic>
      <odom_frame>odom</odom_frame>
      <robot_base_frame>Body0</robot_base_frame>
      <tf_topic>/odom/tf</tf_topic>
    </plugin>

  </gazebo>

  <!-- Color body -->
  <gazebo reference="Body0">
    <material>Gazebo/Black</material>
  </gazebo>
  <!--
    <gazebo reference="Body1">
        <material>Gazebo/Black</material>
    </gazebo>
    <gazebo reference="Body2">
        <material>Gazebo/Black</material>
    </gazebo>
    <gazebo reference="Body3">
        <material>Gazebo/Black</material>
    </gazebo>
    <gazebo reference="Body4">
        <material>Gazebo/Black</material>
    </gazebo>
    -->
</robot>
