<?xml version="1.0" ?>
<!-- =================================================================================== -->
<!-- |    This document was autogenerated by xacro from robot_4leg.xacro               | -->
<!-- |    EDITING THIS FILE BY HAND IS NOT RECOMMENDED                                 | -->
<!-- =================================================================================== -->
<robot name="robot">
  <!-- ~~~~~~ -->
  <!-- macros -->
  <!-- ~~~~~~ -->
  <link name="Body0">
    <inertial>
      <origin rpy="0 0 0" xyz="0.25 0 0"/>
      <mass value="10.0"/>
      <inertia ixx="0.06283333333333334" ixy="0" ixz="0" iyy="0.22708333333333333" iyz="0" izz="0.2524166666666667"/>
    </inertial>
    <visual>
      <origin rpy="0 0 0" xyz="0.25 0 0"/>
      <geometry>
        <box size="0.5 0.23 0.15"/>
      </geometry>
      <material name="Body0_material">
        <color rgba="0 1.0 1.0 1.0"/>
      </material>
    </visual>
    <collision>
      <origin rpy="0 0 0" xyz="0.25 0 0"/>
      <geometry>
        <box size="0.5 0.23 0.15"/>
      </geometry>
    </collision>
  </link>
  <!--
    <xacro:make_continuous_joint name = "Torso3" parent = "Body4" child = "Body3" origin = "${body_x} 0 0" axis = "0 1 0" damping = "0" friction ="0" />
    <xacro:make_continuous_joint name = "Torso2" parent = "Body3" child = "Body2" origin = "${body_x} 0 0" axis = "0 1 0" damping = "0" friction ="0" />
    <xacro:make_continuous_joint name = "Torso1" parent = "Body2" child = "Body1" origin = "${body_x} 0 0" axis = "0 1 0" damping = "0" friction ="0" />
    <xacro:make_continuous_joint name = "Torso0" parent = "Body1" child = "Body0" origin = "${body_x} 0 0" axis = "0 1 0" damping = "0" friction ="0" />
    -->
  <link name="LR0_coxa">
    <inertial>
      <origin rpy="1.57075 0 0" xyz="0 -0.07 0"/>
      <mass value="0.5"/>
      <inertia ixx="0.0012666666666666668" ixy="0" ixz="0" iyy="0.0012666666666666668" iyz="0" izz="0.0009"/>
    </inertial>
    <visual>
      <origin rpy="1.57075 0 0" xyz="0 -0.07 0"/>
      <geometry>
        <cylinder length="0.14" radius="0.06"/>
      </geometry>
      <material name="LR0_coxa_material">
        <color rgba="0 0.0 1.0 1.0"/>
      </material>
    </visual>
    <collision>
      <origin rpy="1.57075 0 0" xyz="0 -0.07 0"/>
      <geometry>
        <cylinder length="0.14" radius="0.06"/>
      </geometry>
    </collision>
  </link>
  <link name="LR0_femur">
    <inertial>
      <origin rpy="1.57075 0 0" xyz="0 -0.14 0"/>
      <mass value="3.0"/>
      <inertia ixx="0.022300000000000004" ixy="0" ixz="0" iyy="0.022300000000000004" iyz="0" izz="0.005399999999999999"/>
    </inertial>
    <visual>
      <origin rpy="1.57075 0 0" xyz="0 -0.14 0"/>
      <geometry>
        <cylinder length="0.28" radius="0.06"/>
      </geometry>
      <material name="LR0_femur_material">
        <color rgba="0 0.0 0.8 1.0"/>
      </material>
    </visual>
    <collision>
      <origin rpy="1.57075 0 0" xyz="0 -0.14 0"/>
      <geometry>
        <cylinder length="0.28" radius="0.06"/>
      </geometry>
    </collision>
  </link>
  <link name="LR0_tibia">
    <inertial>
      <origin rpy="1.57075 0 0" xyz="0 -0.11 0"/>
      <mass value="0.5"/>
      <inertia ixx="0.0024666666666666665" ixy="0" ixz="0" iyy="0.0024666666666666665" iyz="0" izz="0.0009"/>
    </inertial>
    <visual>
      <origin rpy="1.57075 0 0" xyz="0 -0.11 0"/>
      <geometry>
        <cylinder length="0.22" radius="0.06"/>
      </geometry>
      <material name="LR0_tibia_material">
        <color rgba="0 0.0 0.6 1.0"/>
      </material>
    </visual>
    <collision>
      <origin rpy="1.57075 0 0" xyz="0 -0.11 0"/>
      <geometry>
        <cylinder length="0.22" radius="0.06"/>
      </geometry>
    </collision>
  </link>
  <link name="LR0_toe">
    <inertial>
      <origin rpy="0 0 0" xyz="0 0 0"/>
      <mass value="0.3"/>
      <inertia ixx="0.000432" ixy="0" ixz="0" iyy="0.000432" iyz="0" izz="0.000432"/>
    </inertial>
    <visual>
      <origin rpy="0 0 0" xyz="0 0 0"/>
      <geometry>
        <sphere radius="0.06"/>
      </geometry>
      <material name="LR0_toe_material">
        <color rgba="0 0.5 1.0 1.0"/>
      </material>
    </visual>
    <collision name="LR0_toe_collision">
      <origin rpy="0 0 0" xyz="0 0 0"/>
      <geometry>
        <sphere radius="0.06"/>
      </geometry>
    </collision>
  </link>
  <gazebo reference="LR0_toe">
    <material>Gazebo/Red</material>
    <selfCollide>true</selfCollide>
    <sensor name="LR0_toe_sensor" type="contact">
      <contact>
        <collision>LR0_tibia_fixed_joint_lump__LR0_toe_collision_collision_1</collision>
      </contact>
<!--
      <plugin filename="libgazebo_ros_bumper.so" name="gazebo_ros_bumper_controller">
        <alwaysOn>true</alwaysOn>
        <updateRate>100.0</updateRate>
        <bumperTopicName>/mult_robot/LR0_toe_bumper</bumperTopicName>
        <frameName>world</frameName>
      </plugin>
  -->
    </sensor>
    <mu1> 0.2 </mu1>
    <mu2> 0.2 </mu2>
    <maxVel> 1.0 </maxVel>
    <minDepth>0.001</minDepth>
    <kp>5000.0</kp>
    <kd>100.0</kd>
  </gazebo>
  <joint name="lr0_tc" type="continuous">
    <parent link="Body0"/>
    <child link="LR0_coxa"/>
    <origin xyz="0.39 -0.115 0"/>
    <axis xyz="0 1 0"/>
    <calibration rising="0.0"/>
    <dynamics damping="0" friction="0"/>
  </joint>
  <transmission name="tran_lr0_tc">
    <type>transmission_interface/SimpleTransmission</type>
    <joint name="lr0_tc">
      <hardwareInterface>hardware_interface/EffortJointInterface</hardwareInterface>
    </joint>
    <actuator name="motor_lr0_tc">
      <hardwareInterface>hardware_interface/EffortJointInterface</hardwareInterface>
      <mechanicalReduction>1</mechanicalReduction>
    </actuator>
  </transmission>
  <joint name="lr0_ct" type="continuous">
    <parent link="LR0_coxa"/>
    <child link="LR0_femur"/>
    <origin xyz="0 -0.14 0"/>
    <axis xyz="1 0 0"/>
    <calibration rising="0.0"/>
    <dynamics damping="0" friction="0"/>
  </joint>
  <transmission name="tran_lr0_ct">
    <type>transmission_interface/SimpleTransmission</type>
    <joint name="lr0_ct">
      <hardwareInterface>hardware_interface/EffortJointInterface</hardwareInterface>
    </joint>
    <actuator name="motor_lr0_ct">
      <hardwareInterface>hardware_interface/EffortJointInterface</hardwareInterface>
      <mechanicalReduction>1</mechanicalReduction>
    </actuator>
  </transmission>
  <joint name="lr0_ft" type="continuous">
    <parent link="LR0_femur"/>
    <child link="LR0_tibia"/>
    <origin xyz="0 -0.28 0"/>
    <axis xyz="1 0 0"/>
    <calibration rising="0.0"/>
    <dynamics damping="0" friction="0"/>
  </joint>
  <transmission name="tran_lr0_ft">
    <type>transmission_interface/SimpleTransmission</type>
    <joint name="lr0_ft">
      <hardwareInterface>hardware_interface/EffortJointInterface</hardwareInterface>
    </joint>
    <actuator name="motor_lr0_ft">
      <hardwareInterface>hardware_interface/EffortJointInterface</hardwareInterface>
      <mechanicalReduction>1</mechanicalReduction>
    </actuator>
  </transmission>
  <joint name="LR0_TOE" type="fixed">
    <parent link="LR0_tibia"/>
    <child link="LR0_toe"/>
    <origin xyz="0 -0.22 0"/>
  </joint>
  <link name="LL0_coxa">
    <inertial>
      <origin rpy="-1.57075 0 0" xyz="0 0.07 0"/>
      <mass value="0.5"/>
      <inertia ixx="0.0012666666666666668" ixy="0" ixz="0" iyy="0.0012666666666666668" iyz="0" izz="0.0009"/>
    </inertial>
    <visual>
      <origin rpy="-1.57075 0 0" xyz="0 0.07 0"/>
      <geometry>
        <cylinder length="0.14" radius="0.06"/>
      </geometry>
      <material name="LL0_coxa_material">
        <color rgba="0 0.0 1.0 1.0"/>
      </material>
    </visual>
    <collision>
      <origin rpy="-1.57075 0 0" xyz="0 0.07 0"/>
      <geometry>
        <cylinder length="0.14" radius="0.06"/>
      </geometry>
    </collision>
  </link>
  <link name="LL0_femur">
    <inertial>
      <origin rpy="-1.57075 0 0" xyz="0 0.14 0"/>
      <mass value="3.0"/>
      <inertia ixx="0.022300000000000004" ixy="0" ixz="0" iyy="0.022300000000000004" iyz="0" izz="0.005399999999999999"/>
    </inertial>
    <visual>
      <origin rpy="-1.57075 0 0" xyz="0 0.14 0"/>
      <geometry>
        <cylinder length="0.28" radius="0.06"/>
      </geometry>
      <material name="LL0_femur_material">
        <color rgba="0 0.0 0.8 1.0"/>
      </material>
    </visual>
    <collision>
      <origin rpy="-1.57075 0 0" xyz="0 0.14 0"/>
      <geometry>
        <cylinder length="0.28" radius="0.06"/>
      </geometry>
    </collision>
  </link>
  <link name="LL0_tibia">
    <inertial>
      <origin rpy="-1.57075 0 0" xyz="0 0.11 0"/>
      <mass value="0.5"/>
      <inertia ixx="0.0024666666666666665" ixy="0" ixz="0" iyy="0.0024666666666666665" iyz="0" izz="0.0009"/>
    </inertial>
    <visual>
      <origin rpy="-1.57075 0 0" xyz="0 0.11 0"/>
      <geometry>
        <cylinder length="0.22" radius="0.06"/>
      </geometry>
      <material name="LL0_tibia_material">
        <color rgba="0 0.0 0.6 1.0"/>
      </material>
    </visual>
    <collision>
      <origin rpy="-1.57075 0 0" xyz="0 0.11 0"/>
      <geometry>
        <cylinder length="0.22" radius="0.06"/>
      </geometry>
    </collision>
  </link>
  <link name="LL0_toe">
    <inertial>
      <origin rpy="0 0 0" xyz="0 0 0"/>
      <mass value="0.3"/>
      <inertia ixx="0.000432" ixy="0" ixz="0" iyy="0.000432" iyz="0" izz="0.000432"/>
    </inertial>
    <visual>
      <origin rpy="0 0 0" xyz="0 0 0"/>
      <geometry>
        <sphere radius="0.06"/>
      </geometry>
      <material name="LL0_toe_material">
        <color rgba="0 0.5 1.0 1.0"/>
      </material>
    </visual>
    <collision name="LL0_toe_collision">
      <origin rpy="0 0 0" xyz="0 0 0"/>
      <geometry>
        <sphere radius="0.06"/>
      </geometry>
    </collision>
  </link>
  <gazebo reference="LL0_toe">
    <material>Gazebo/Red</material>
    <selfCollide>true</selfCollide>
    <sensor name="LL0_toe_sensor" type="contact">
      <contact>
        <collision>LL0_tibia_fixed_joint_lump__LL0_toe_collision_collision_1</collision>
      </contact>
<!--
      <plugin filename="libgazebo_ros_bumper.so" name="gazebo_ros_bumper_controller">
        <alwaysOn>true</alwaysOn>
        <updateRate>100.0</updateRate>
        <bumperTopicName>/mult_robot/LL0_toe_bumper</bumperTopicName>
        <frameName>world</frameName>
      </plugin>
  -->
    </sensor>
    <mu1> 0.2 </mu1>
    <mu2> 0.2 </mu2>
    <maxVel> 1.0 </maxVel>
    <minDepth>0.001</minDepth>
    <kp>5000.0</kp>
    <kd>100.0</kd>
  </gazebo>
  <joint name="ll0_tc" type="continuous">
    <parent link="Body0"/>
    <child link="LL0_coxa"/>
    <origin xyz="0.39 0.115 0"/>
    <axis xyz="0 1 0"/>
    <calibration rising="0.0"/>
    <dynamics damping="0" friction="0"/>
  </joint>
  <transmission name="tran_ll0_tc">
    <type>transmission_interface/SimpleTransmission</type>
    <joint name="ll0_tc">
      <hardwareInterface>hardware_interface/EffortJointInterface</hardwareInterface>
    </joint>
    <actuator name="motor_ll0_tc">
      <hardwareInterface>hardware_interface/EffortJointInterface</hardwareInterface>
      <mechanicalReduction>1</mechanicalReduction>
    </actuator>
  </transmission>
  <joint name="ll0_ct" type="continuous">
    <parent link="LL0_coxa"/>
    <child link="LL0_femur"/>
    <origin xyz="0 0.14 0"/>
    <axis xyz="1 0 0"/>
    <calibration rising="0.0"/>
    <dynamics damping="0" friction="0"/>
  </joint>
  <transmission name="tran_ll0_ct">
    <type>transmission_interface/SimpleTransmission</type>
    <joint name="ll0_ct">
      <hardwareInterface>hardware_interface/EffortJointInterface</hardwareInterface>
    </joint>
    <actuator name="motor_ll0_ct">
      <hardwareInterface>hardware_interface/EffortJointInterface</hardwareInterface>
      <mechanicalReduction>1</mechanicalReduction>
    </actuator>
  </transmission>
  <joint name="ll0_ft" type="continuous">
    <parent link="LL0_femur"/>
    <child link="LL0_tibia"/>
    <origin xyz="0 0.28 0"/>
    <axis xyz="1 0 0"/>
    <calibration rising="0.0"/>
    <dynamics damping="0" friction="0"/>
  </joint>
  <transmission name="tran_ll0_ft">
    <type>transmission_interface/SimpleTransmission</type>
    <joint name="ll0_ft">
      <hardwareInterface>hardware_interface/EffortJointInterface</hardwareInterface>
    </joint>
    <actuator name="motor_ll0_ft">
      <hardwareInterface>hardware_interface/EffortJointInterface</hardwareInterface>
      <mechanicalReduction>1</mechanicalReduction>
    </actuator>
  </transmission>
  <joint name="LL0_TOE" type="fixed">
    <parent link="LL0_tibia"/>
    <child link="LL0_toe"/>
    <origin xyz="0 0.22 0"/>
  </joint>
  <link name="LR1_coxa">
    <inertial>
      <origin rpy="1.57075 0 0" xyz="0 -0.07 0"/>
      <mass value="0.5"/>
      <inertia ixx="0.0012666666666666668" ixy="0" ixz="0" iyy="0.0012666666666666668" iyz="0" izz="0.0009"/>
    </inertial>
    <visual>
      <origin rpy="1.57075 0 0" xyz="0 -0.07 0"/>
      <geometry>
        <cylinder length="0.14" radius="0.06"/>
      </geometry>
      <material name="LR1_coxa_material">
        <color rgba="0 0.0 1.0 1.0"/>
      </material>
    </visual>
    <collision>
      <origin rpy="1.57075 0 0" xyz="0 -0.07 0"/>
      <geometry>
        <cylinder length="0.14" radius="0.06"/>
      </geometry>
    </collision>
  </link>
  <link name="LR1_femur">
    <inertial>
      <origin rpy="1.57075 0 0" xyz="0 -0.14 0"/>
      <mass value="3.0"/>
      <inertia ixx="0.022300000000000004" ixy="0" ixz="0" iyy="0.022300000000000004" iyz="0" izz="0.005399999999999999"/>
    </inertial>
    <visual>
      <origin rpy="1.57075 0 0" xyz="0 -0.14 0"/>
      <geometry>
        <cylinder length="0.28" radius="0.06"/>
      </geometry>
      <material name="LR1_femur_material">
        <color rgba="0 0.0 0.8 1.0"/>
      </material>
    </visual>
    <collision>
      <origin rpy="1.57075 0 0" xyz="0 -0.14 0"/>
      <geometry>
        <cylinder length="0.28" radius="0.06"/>
      </geometry>
    </collision>
  </link>
  <link name="LR1_tibia">
    <inertial>
      <origin rpy="1.57075 0 0" xyz="0 -0.11 0"/>
      <mass value="0.5"/>
      <inertia ixx="0.0024666666666666665" ixy="0" ixz="0" iyy="0.0024666666666666665" iyz="0" izz="0.0009"/>
    </inertial>
    <visual>
      <origin rpy="1.57075 0 0" xyz="0 -0.11 0"/>
      <geometry>
        <cylinder length="0.22" radius="0.06"/>
      </geometry>
      <material name="LR1_tibia_material">
        <color rgba="0 0.0 0.6 1.0"/>
      </material>
    </visual>
    <collision>
      <origin rpy="1.57075 0 0" xyz="0 -0.11 0"/>
      <geometry>
        <cylinder length="0.22" radius="0.06"/>
      </geometry>
    </collision>
  </link>
  <link name="LR1_toe">
    <inertial>
      <origin rpy="0 0 0" xyz="0 0 0"/>
      <mass value="0.3"/>
      <inertia ixx="0.000432" ixy="0" ixz="0" iyy="0.000432" iyz="0" izz="0.000432"/>
    </inertial>
    <visual>
      <origin rpy="0 0 0" xyz="0 0 0"/>
      <geometry>
        <sphere radius="0.06"/>
      </geometry>
      <material name="LR1_toe_material">
        <color rgba="0 0.5 1.0 1.0"/>
      </material>
    </visual>
    <collision name="LR1_toe_collision">
      <origin rpy="0 0 0" xyz="0 0 0"/>
      <geometry>
        <sphere radius="0.06"/>
      </geometry>
    </collision>
  </link>
  <gazebo reference="LR1_toe">
    <material>Gazebo/Red</material>
    <selfCollide>true</selfCollide>
    <sensor name="LR1_toe_sensor" type="contact">
      <contact>
        <collision>LR1_tibia_fixed_joint_lump__LR1_toe_collision_collision_1</collision>
      </contact>
<!--
      <plugin filename="libgazebo_ros_bumper.so" name="gazebo_ros_bumper_controller">
        <alwaysOn>true</alwaysOn>
        <updateRate>100.0</updateRate>
        <bumperTopicName>/mult_robot/LR1_toe_bumper</bumperTopicName>
        <frameName>world</frameName>
      </plugin>
  -->
    </sensor>
    <mu1> 0.2 </mu1>
    <mu2> 0.2 </mu2>
    <maxVel> 1.0 </maxVel>
    <minDepth>0.001</minDepth>
    <kp>5000.0</kp>
    <kd>100.0</kd>
  </gazebo>
  <joint name="lr1_tc" type="continuous">
    <parent link="Body0"/>
    <child link="LR1_coxa"/>
    <origin xyz="0.11 -0.115 0"/>
    <axis xyz="0 1 0"/>
    <calibration rising="0.0"/>
    <dynamics damping="0" friction="0"/>
  </joint>
  <transmission name="tran_lr1_tc">
    <type>transmission_interface/SimpleTransmission</type>
    <joint name="lr1_tc">
      <hardwareInterface>hardware_interface/EffortJointInterface</hardwareInterface>
    </joint>
    <actuator name="motor_lr1_tc">
      <hardwareInterface>hardware_interface/EffortJointInterface</hardwareInterface>
      <mechanicalReduction>1</mechanicalReduction>
    </actuator>
  </transmission>
  <joint name="lr1_ct" type="continuous">
    <parent link="LR1_coxa"/>
    <child link="LR1_femur"/>
    <origin xyz="0 -0.14 0"/>
    <axis xyz="1 0 0"/>
    <calibration rising="0.0"/>
    <dynamics damping="0" friction="0"/>
  </joint>
  <transmission name="tran_lr1_ct">
    <type>transmission_interface/SimpleTransmission</type>
    <joint name="lr1_ct">
      <hardwareInterface>hardware_interface/EffortJointInterface</hardwareInterface>
    </joint>
    <actuator name="motor_lr1_ct">
      <hardwareInterface>hardware_interface/EffortJointInterface</hardwareInterface>
      <mechanicalReduction>1</mechanicalReduction>
    </actuator>
  </transmission>
  <joint name="lr1_ft" type="continuous">
    <parent link="LR1_femur"/>
    <child link="LR1_tibia"/>
    <origin xyz="0 -0.28 0"/>
    <axis xyz="1 0 0"/>
    <calibration rising="0.0"/>
    <dynamics damping="0" friction="0"/>
  </joint>
  <transmission name="tran_lr1_ft">
    <type>transmission_interface/SimpleTransmission</type>
    <joint name="lr1_ft">
      <hardwareInterface>hardware_interface/EffortJointInterface</hardwareInterface>
    </joint>
    <actuator name="motor_lr1_ft">
      <hardwareInterface>hardware_interface/EffortJointInterface</hardwareInterface>
      <mechanicalReduction>1</mechanicalReduction>
    </actuator>
  </transmission>
  <joint name="LR1_TOE" type="fixed">
    <parent link="LR1_tibia"/>
    <child link="LR1_toe"/>
    <origin xyz="0 -0.22 0"/>
  </joint>
  <link name="LL1_coxa">
    <inertial>
      <origin rpy="-1.57075 0 0" xyz="0 0.07 0"/>
      <mass value="0.5"/>
      <inertia ixx="0.0012666666666666668" ixy="0" ixz="0" iyy="0.0012666666666666668" iyz="0" izz="0.0009"/>
    </inertial>
    <visual>
      <origin rpy="-1.57075 0 0" xyz="0 0.07 0"/>
      <geometry>
        <cylinder length="0.14" radius="0.06"/>
      </geometry>
      <material name="LL1_coxa_material">
        <color rgba="0 0.0 1.0 1.0"/>
      </material>
    </visual>
    <collision>
      <origin rpy="-1.57075 0 0" xyz="0 0.07 0"/>
      <geometry>
        <cylinder length="0.14" radius="0.06"/>
      </geometry>
    </collision>
  </link>
  <link name="LL1_femur">
    <inertial>
      <origin rpy="-1.57075 0 0" xyz="0 0.14 0"/>
      <mass value="3.0"/>
      <inertia ixx="0.022300000000000004" ixy="0" ixz="0" iyy="0.022300000000000004" iyz="0" izz="0.005399999999999999"/>
    </inertial>
    <visual>
      <origin rpy="-1.57075 0 0" xyz="0 0.14 0"/>
      <geometry>
        <cylinder length="0.28" radius="0.06"/>
      </geometry>
      <material name="LL1_femur_material">
        <color rgba="0 0.0 0.8 1.0"/>
      </material>
    </visual>
    <collision>
      <origin rpy="-1.57075 0 0" xyz="0 0.14 0"/>
      <geometry>
        <cylinder length="0.28" radius="0.06"/>
      </geometry>
    </collision>
  </link>
  <link name="LL1_tibia">
    <inertial>
      <origin rpy="-1.57075 0 0" xyz="0 0.11 0"/>
      <mass value="0.5"/>
      <inertia ixx="0.0024666666666666665" ixy="0" ixz="0" iyy="0.0024666666666666665" iyz="0" izz="0.0009"/>
    </inertial>
    <visual>
      <origin rpy="-1.57075 0 0" xyz="0 0.11 0"/>
      <geometry>
        <cylinder length="0.22" radius="0.06"/>
      </geometry>
      <material name="LL1_tibia_material">
        <color rgba="0 0.0 0.6 1.0"/>
      </material>
    </visual>
    <collision>
      <origin rpy="-1.57075 0 0" xyz="0 0.11 0"/>
      <geometry>
        <cylinder length="0.22" radius="0.06"/>
      </geometry>
    </collision>
  </link>
  <link name="LL1_toe">
    <inertial>
      <origin rpy="0 0 0" xyz="0 0 0"/>
      <mass value="0.3"/>
      <inertia ixx="0.000432" ixy="0" ixz="0" iyy="0.000432" iyz="0" izz="0.000432"/>
    </inertial>
    <visual>
      <origin rpy="0 0 0" xyz="0 0 0"/>
      <geometry>
        <sphere radius="0.06"/>
      </geometry>
      <material name="LL1_toe_material">
        <color rgba="0 0.5 1.0 1.0"/>
      </material>
    </visual>
    <collision name="LL1_toe_collision">
      <origin rpy="0 0 0" xyz="0 0 0"/>
      <geometry>
        <sphere radius="0.06"/>
      </geometry>
    </collision>
  </link>
  <gazebo reference="LL1_toe">
    <material>Gazebo/Red</material>
    <selfCollide>true</selfCollide>
    <sensor name="LL1_toe_sensor" type="contact">
      <contact>
        <collision>LL1_tibia_fixed_joint_lump__LL1_toe_collision_collision_1</collision>
      </contact>
<!--
      <plugin filename="libgazebo_ros_bumper.so" name="gazebo_ros_bumper_controller">
        <alwaysOn>true</alwaysOn>
        <updateRate>100.0</updateRate>
        <bumperTopicName>/mult_robot/LL1_toe_bumper</bumperTopicName>
        <frameName>world</frameName>
      </plugin>
-->
    </sensor>
    <mu1> 0.2 </mu1>
    <mu2> 0.2 </mu2>
    <maxVel> 1.0 </maxVel>
    <minDepth>0.001</minDepth>
    <kp>5000.0</kp>
    <kd>100.0</kd>
  </gazebo>
  <joint name="ll1_tc" type="continuous">
    <parent link="Body0"/>
    <child link="LL1_coxa"/>
    <origin xyz="0.11 0.115 0"/>
    <axis xyz="0 1 0"/>
    <calibration rising="0.0"/>
    <dynamics damping="0" friction="0"/>
  </joint>
  <transmission name="tran_ll1_tc">
    <type>transmission_interface/SimpleTransmission</type>
    <joint name="ll1_tc">
      <hardwareInterface>hardware_interface/EffortJointInterface</hardwareInterface>
    </joint>
    <actuator name="motor_ll1_tc">
      <hardwareInterface>hardware_interface/EffortJointInterface</hardwareInterface>
      <mechanicalReduction>1</mechanicalReduction>
    </actuator>
  </transmission>
  <joint name="ll1_ct" type="continuous">
    <parent link="LL1_coxa"/>
    <child link="LL1_femur"/>
    <origin xyz="0 0.14 0"/>
    <axis xyz="1 0 0"/>
    <calibration rising="0.0"/>
    <dynamics damping="0" friction="0"/>
  </joint>
  <transmission name="tran_ll1_ct">
    <type>transmission_interface/SimpleTransmission</type>
    <joint name="ll1_ct">
      <hardwareInterface>hardware_interface/EffortJointInterface</hardwareInterface>
    </joint>
    <actuator name="motor_ll1_ct">
      <hardwareInterface>hardware_interface/EffortJointInterface</hardwareInterface>
      <mechanicalReduction>1</mechanicalReduction>
    </actuator>
  </transmission>
  <joint name="ll1_ft" type="continuous">
    <parent link="LL1_femur"/>
    <child link="LL1_tibia"/>
    <origin xyz="0 0.28 0"/>
    <axis xyz="1 0 0"/>
    <calibration rising="0.0"/>
    <dynamics damping="0" friction="0"/>-->
  </joint>
  <transmission name="tran_ll1_ft">
    <type>transmission_interface/SimpleTransmission</type>
    <joint name="ll1_ft">
      <hardwareInterface>hardware_interface/EffortJointInterface</hardwareInterface>
    </joint>
    <actuator name="motor_ll1_ft">
      <hardwareInterface>hardware_interface/EffortJointInterface</hardwareInterface>
      <mechanicalReduction>1</mechanicalReduction>
    </actuator>
  </transmission>
  <joint name="LL1_TOE" type="fixed">
    <parent link="LL1_tibia"/>
    <child link="LL1_toe"/>
    <origin xyz="0 0.22 0"/>
  </joint>
  <!--
    <xacro:make_right_leg name = "LR1" body = "Body1"  legOrigin="${body_x/2} ${-body_y / 2} 0" coxaLength= "${coxa_l}" coxaMass="${coxa_m}" femurLength="${femur_l}" femurMass="${femur_m}" tibiaLength="${tibia_l}" tibiaMass="${tibia_m}" 
        toeMass="${toe_m}" radius="${radius}" damping="0" friction="0" collision="LR1_tibia_fixed_joint_lump__LR1_toe_collision_collision_1" />
    <xacro:make_left_leg name = "LL1" body = "Body1"  legOrigin="${body_x/2} ${body_y / 2} 0" coxaLength="${coxa_l}" coxaMass="${coxa_m}" femurLength="${femur_l}" femurMass="${femur_m}" tibiaLength="${tibia_l}" tibiaMass="${tibia_m}" 
        toeMass="${toe_m}" radius="${radius}" damping="0" friction="0" collision="LL1_tibia_fixed_joint_lump__LL1_toe_collision_collision_1" />
    <xacro:make_right_leg name = "LR2" body = "Body2"  legOrigin="${body_x/2} ${-body_y / 2} 0" coxaLength= "${coxa_l}" coxaMass="${coxa_m}" femurLength="${femur_l}" femurMass="${femur_m}" tibiaLength="${tibia_l}" tibiaMass="${tibia_m}" 
        toeMass="${toe_m}" radius="${radius}" damping="0" friction="0" collision="LR2_tibia_fixed_joint_lump__LR2_toe_collision_collision_1" />
    <xacro:make_left_leg name = "LL2" body = "Body2"  legOrigin="${body_x/2} ${body_y / 2} 0" coxaLength="${coxa_l}" coxaMass="${coxa_m}" femurLength="${femur_l}" femurMass="${femur_m}" tibiaLength="${tibia_l}" tibiaMass="${tibia_m}" 
        toeMass="${toe_m}" radius="${radius}" damping="0" friction="0" collision="LL2_tibia_fixed_joint_lump__LL2_toe_collision_collision_1" />
    <xacro:make_right_leg name = "LR3" body = "Body3"  legOrigin="${body_x/2} ${-body_y / 2} 0" coxaLength= "${coxa_l}" coxaMass="${coxa_m}" femurLength="${femur_l}" femurMass="${femur_m}" tibiaLength="${tibia_l}" tibiaMass="${tibia_m}" 
        toeMass="${toe_m}" radius="${radius}" damping="0" friction="0" collision="LR3_tibia_fixed_joint_lump__LR3_toe_collision_collision_1" />
    <xacro:make_left_leg name = "LL3" body = "Body3"  legOrigin="${body_x/2} ${body_y / 2} 0" coxaLength="${coxa_l}" coxaMass="${coxa_m}" femurLength="${femur_l}" femurMass="${femur_m}" tibiaLength="${tibia_l}" tibiaMass="${tibia_m}" 
        toeMass="${toe_m}" radius="${radius}" damping="0" friction="0"  collision="LL3_tibia_fixed_joint_lump__LL3_toe_collision_collision_1"/>
    <xacro:make_right_leg name = "LR4" body = "Body4"  legOrigin="${body_x/2} ${-body_y / 2} 0" coxaLength= "${coxa_l}" coxaMass="${coxa_m}" femurLength="${femur_l}" femurMass="${femur_m}" tibiaLength="${tibia_l}" tibiaMass="${tibia_m}" 
        toeMass="${toe_m}" radius="${radius}" damping="0" friction="0" collision="LR4_tibia_fixed_joint_lump__LR4_toe_collision_collision_1"/>
    <xacro:make_left_leg name = "LL4" body = "Body4"  legOrigin="${body_x/2} ${body_y / 2} 0" coxaLength="${coxa_l}" coxaMass="${coxa_m}" femurLength="${femur_l}" femurMass="${femur_m}" tibiaLength="${tibia_l}" tibiaMass="${tibia_m}" 
        toeMass="${toe_m}" radius="${radius}" damping="0" friction="0" collision="LL4_tibia_fixed_joint_lump__LL4_toe_collision_collision_1"/>
    -->


  <!-- ros_control plugin -->
   <!-- ros2_control plugin -->
<!-- ros2_control -->
  <ros2_control name="IgnitionSystem" type="system">
    <hardware>
      <plugin>ign_ros2_control/IgnitionSystem</plugin>
    </hardware>
 
      <!-- Rev Link Right side -->
    <joint name="lr0_tc">
      <command_interface name="effort">
        <param name="min">-100</param>
        <param name="max">100</param>
      </command_interface>
      <state_interface name="position"/>
      <state_interface name="velocity"/>
      <state_interface name="effort"/>
    </joint>
    <joint name="lr0_ct">
      <command_interface name="effort">
        <param name="min">-100</param>
        <param name="max">100</param>
      </command_interface>
      <state_interface name="position"/>
      <state_interface name="velocity"/>
      <state_interface name="effort"/>
    </joint>
    <joint name="lr0_ft">
      <command_interface name="effort">
        <param name="min">-100</param>
        <param name="max">100</param>
      </command_interface>
      <state_interface name="position"/>
      <state_interface name="velocity"/>
      <state_interface name="effort"/>
    </joint>
    <joint name="lr1_tc">
      <command_interface name="effort">
        <param name="min">-100</param>
        <param name="max">100</param>
      </command_interface>
      <state_interface name="position"/>
      <state_interface name="velocity"/>
      <state_interface name="effort"/>
    </joint>
    <joint name="lr1_ct">
      <command_interface name="effort">
        <param name="min">-100</param>
        <param name="max">100</param>
      </command_interface>
      <state_interface name="position"/>
      <state_interface name="velocity"/>
      <state_interface name="effort"/>
    </joint>
    <joint name="lr1_ft">
      <command_interface name="effort">
        <param name="min">-100</param>
        <param name="max">100</param>
      </command_interface>
      <state_interface name="position"/>
      <state_interface name="velocity"/>
      <state_interface name="effort"/>
    </joint>

     <!-- Rev Link Left side -->
    <joint name="ll0_tc">
      <command_interface name="effort">
        <param name="min">-100</param>
        <param name="max">100</param>
      </command_interface>
      <state_interface name="position"/>
      <state_interface name="velocity"/>
      <state_interface name="effort"/>
    </joint>
    <joint name="ll0_ct">
      <command_interface name="effort">
        <param name="min">-100</param>
        <param name="max">100</param>
      </command_interface>
      <state_interface name="position"/>
      <state_interface name="velocity"/>
      <state_interface name="effort"/>
    </joint>
    <joint name="ll0_ft">
      <command_interface name="effort">
        <param name="min">-100</param>
        <param name="max">100</param>
      </command_interface>
      <state_interface name="position"/>
      <state_interface name="velocity"/>
      <state_interface name="effort"/>
    </joint>
    <joint name="ll1_tc">
      <command_interface name="effort">
        <param name="min">-100</param>
        <param name="max">100</param>
      </command_interface>
      <state_interface name="position"/>
      <state_interface name="velocity"/>
      <state_interface name="effort"/>
    </joint>
    <joint name="ll1_ct">
      <command_interface name="effort">
        <param name="min">-100</param>
        <param name="max">100</param>
      </command_interface>
      <state_interface name="position"/>
      <state_interface name="velocity"/>
      <state_interface name="effort"/>
    </joint>
    <joint name="ll1_ft">
      <command_interface name="effort">
        <param name="min">-100</param>
        <param name="max">100</param>
      </command_interface>
      <state_interface name="position"/>
      <state_interface name="velocity"/>
      <state_interface name="effort"/>
    </joint>

  </ros2_control>

  <!-- ros2_control -->
  <gazebo>
    <!-- <plugin filename="libgazebo_ros2_control.so" name="gazebo_ros2_control"> -->
    <plugin name="ign_ros2_control::IgnitionROS2ControlPlugin" filename="ign_ros2_control-system">     <!-- <robot_param>robot_description</robot_param> -->
     <!-- <robot_param_node>robot_state_publisher</robot_param_node> -->
      <!-- <parameters>$(find manta_v2_gazebo_ros2_control)/config/manta_v2_moveit_controller.yaml</parameters> -->
     <parameters>$(find robot_gazebo_ros2_control)/config/robot_trajectory_controller.yaml</parameters>  
      <!--<parameters>$(find robot_gazebo_ros2_control)/config/robot_effort_controller.yaml</parameters> -->
     <controller_manager_prefix_node_name>controller_manager</controller_manager_prefix_node_name>
    </plugin>
  </gazebo>

  <!-- Color body -->
  <gazebo reference="Body0">
    <material>Gazebo/Black</material>
  </gazebo>
  <!--
    <gazebo reference="Body1">
        <material>Gazebo/Black</material>
    </gazebo>
    <gazebo reference="Body2">
        <material>Gazebo/Black</material>
    </gazebo>
    <gazebo reference="Body3">
        <material>Gazebo/Black</material>
    </gazebo>
    <gazebo reference="Body4">
        <material>Gazebo/Black</material>
    </gazebo>
    -->
</robot>
