<?xml version="1.0" ?>
<!-- =================================================================================== -->
<!-- |    This document was autogenerated by xacro from robot_5wheel.xacro             | -->
<!-- |    EDITING THIS FILE BY HAND IS NOT RECOMMENDED                                 | -->
<!-- =================================================================================== -->
<robot name="robot_5wheel">
  <!-- ~~~~~~ -->
  <!-- macros -->
  <!-- ~~~~~~ -->
  <link name="Body0">
    <inertial>
      <origin rpy="0 0 0" xyz="0.29 0 0"/>
      <mass value="10.0"/>
      <inertia ixx="0.06283333333333334" ixy="0" ixz="0" iyy="0.2990833333333333" iyz="0" izz="0.32441666666666663"/>
    </inertial>
    <visual>
      <origin rpy="0 0 0" xyz="0.29 0 0"/>
      <geometry>
        <box size="0.58 0.23 0.15"/>
      </geometry>
      <material name="Body0_material">
        <color rgba="0 1.0 1.0 1.0"/>
      </material>
    </visual>
    <collision>
      <origin rpy="0 0 0" xyz="0.29 0 0"/>
      <geometry>
        <box size="0.58 0.23 0.15"/>
      </geometry>
    </collision>
  </link>
  <!--
    <xacro:make_continuous_joint name = "Torso3" parent = "Body4" child = "Body3" origin = "${body_x} 0 0" axis = "0 1 0" damping = "0" friction ="0" />
    <xacro:make_continuous_joint name = "Torso2" parent = "Body3" child = "Body2" origin = "${body_x} 0 0" axis = "0 1 0" damping = "0" friction ="0" />
    <xacro:make_continuous_joint name = "Torso1" parent = "Body2" child = "Body1" origin = "${body_x} 0 0" axis = "0 1 0" damping = "0" friction ="0" />
    <xacro:make_continuous_joint name = "Torso0" parent = "Body1" child = "Body0" origin = "${body_x} 0 0" axis = "0 1 0" damping = "0" friction ="0" />
    -->
  <link name="LR0_coxa">
    <inertial>
      <origin rpy="1.57075 0 0" xyz="0 -0.07 0"/>
      <mass value="0.5"/>
      <inertia ixx="0.0012666666666666668" ixy="0" ixz="0" iyy="0.0012666666666666668" iyz="0" izz="0.0009"/>
    </inertial>
    <visual>
      <origin rpy="1.57075 0 0" xyz="0 -0.07 0"/>
      <geometry>
        <cylinder length="0.14" radius="0.06"/>
      </geometry>
      <material name="LR0_coxa_material">
        <color rgba="0 0.0 1.0 1.0"/>
      </material>
    </visual>
    <collision>
      <origin rpy="1.57075 0 0" xyz="0 -0.07 0"/>
      <geometry>
        <cylinder length="0.14" radius="0.06"/>
      </geometry>
    </collision>
  </link>
  <link name="LR0_femur">
    <inertial>
      <origin rpy="1.57075 0 0" xyz="0 -0.14 0"/>
      <mass value="3.0"/>
      <inertia ixx="0.022300000000000004" ixy="0" ixz="0" iyy="0.022300000000000004" iyz="0" izz="0.005399999999999999"/>
    </inertial>
    <visual>
      <origin rpy="1.57075 0 0" xyz="0 -0.14 0"/>
      <geometry>
        <cylinder length="0.28" radius="0.06"/>
      </geometry>
      <material name="LR0_femur_material">
        <color rgba="0 0.0 0.8 1.0"/>
      </material>
    </visual>
    <collision>
      <origin rpy="1.57075 0 0" xyz="0 -0.14 0"/>
      <geometry>
        <cylinder length="0.28" radius="0.06"/>
      </geometry>
    </collision>
  </link>
  <link name="LR0_tibia">
    <inertial>
      <origin rpy="1.57075 0 0" xyz="0 -0.07 0"/>
      <mass value="0.5"/>
      <inertia ixx="0.0012666666666666668" ixy="0" ixz="0" iyy="0.0012666666666666668" iyz="0" izz="0.0009"/>
    </inertial>
    <visual>
      <origin rpy="1.57075 0 0" xyz="0 -0.07 0"/>
      <geometry>
        <cylinder length="0.14" radius="0.06"/>
      </geometry>
      <material name="LR0_tibia_material">
        <color rgba="0 0.0 0.6 1.0"/>
      </material>
    </visual>
    <collision>
      <origin rpy="1.57075 0 0" xyz="0 -0.07 0"/>
      <geometry>
        <cylinder length="0.14" radius="0.06"/>
      </geometry>
    </collision>
  </link>
  <link name="LR0_wheel">
    <inertial>
      <origin rpy="1.57075 0 0" xyz="0 -0.05 0"/>
      <mass value="0.3"/>
      <inertia ixx="0.004046875" ixy="0" ixz="0" iyy="0.004046875" iyz="0" izz="0.007593750000000001"/>
    </inertial>
    <visual>
      <origin rpy="1.57075 0 0" xyz="0 -0.05 0"/>
      <geometry>
        <cylinder length="0.1" radius="0.225"/>
      </geometry>
      <material name="LR0_wheel_material">
        <color rgba="0 0.5 1.0 1.0"/>
      </material>
    </visual>
    <collision>
      <origin rpy="1.57075 0 0" xyz="0 -0.05 0"/>
      <geometry>
        <cylinder length="0.1" radius="0.225"/>
      </geometry>
    </collision>
  </link>
  <joint name="LR0_TC" type="continuous">
    <parent link="Body0"/>
    <child link="LR0_coxa"/>
    <origin xyz="0.43 -0.115 0"/>
    <axis xyz="0 1 0"/>
    <calibration rising="0.0"/>
    <dynamics damping="0" friction="0"/>
  </joint>
  <transmission name="tran_LR0_TC">
    <type>transmission_interface/SimpleTransmission</type>
    <joint name="LR0_TC">
      <hardwareInterface>hardware_interface/EffortJointInterface</hardwareInterface>
    </joint>
    <actuator name="motor_LR0_TC">
      <hardwareInterface>hardware_interface/EffortJointInterface</hardwareInterface>
      <mechanicalReduction>1</mechanicalReduction>
    </actuator>
  </transmission>
  <joint name="LR0_CT" type="continuous">
    <parent link="LR0_coxa"/>
    <child link="LR0_femur"/>
    <origin xyz="0 -0.14 0"/>
    <axis xyz="1 0 0"/>
    <calibration rising="0.0"/>
    <dynamics damping="0" friction="0"/>
  </joint>
  <transmission name="tran_LR0_CT">
    <type>transmission_interface/SimpleTransmission</type>
    <joint name="LR0_CT">
      <hardwareInterface>hardware_interface/EffortJointInterface</hardwareInterface>
    </joint>
    <actuator name="motor_LR0_CT">
      <hardwareInterface>hardware_interface/EffortJointInterface</hardwareInterface>
      <mechanicalReduction>1</mechanicalReduction>
    </actuator>
  </transmission>
  <joint name="LR0_FT" type="continuous">
    <parent link="LR0_femur"/>
    <child link="LR0_tibia"/>
    <origin xyz="0 -0.28 0"/>
    <axis xyz="1 0 0"/>
    <calibration rising="0.0"/>
    <dynamics damping="0" friction="0"/>
  </joint>
  <transmission name="tran_LR0_FT">
    <type>transmission_interface/SimpleTransmission</type>
    <joint name="LR0_FT">
      <hardwareInterface>hardware_interface/EffortJointInterface</hardwareInterface>
    </joint>
    <actuator name="motor_LR0_FT">
      <hardwareInterface>hardware_interface/EffortJointInterface</hardwareInterface>
      <mechanicalReduction>1</mechanicalReduction>
    </actuator>
  </transmission>
  <joint name="LR0_WH" type="continuous">
    <parent link="LR0_tibia"/>
    <child link="LR0_wheel"/>
    <origin xyz="0 -0.14 0"/>
    <axis xyz="0 1 0"/>
    <calibration rising="0.0"/>
    <dynamics damping="0" friction="0"/>
  </joint>
  <transmission name="tran_LR0_WH">
    <type>transmission_interface/SimpleTransmission</type>
    <joint name="LR0_WH">
      <hardwareInterface>hardware_interface/EffortJointInterface</hardwareInterface>
    </joint>
    <actuator name="motor_LR0_WH">
      <hardwareInterface>hardware_interface/EffortJointInterface</hardwareInterface>
      <mechanicalReduction>1</mechanicalReduction>
    </actuator>
  </transmission>
  <link name="LL0_coxa">
    <inertial>
      <origin rpy="-1.57075 0 0" xyz="0 0.07 0"/>
      <mass value="0.5"/>
      <inertia ixx="0.0012666666666666668" ixy="0" ixz="0" iyy="0.0012666666666666668" iyz="0" izz="0.0009"/>
    </inertial>
    <visual>
      <origin rpy="-1.57075 0 0" xyz="0 0.07 0"/>
      <geometry>
        <cylinder length="0.14" radius="0.06"/>
      </geometry>
      <material name="LL0_coxa_material">
        <color rgba="0 0.0 1.0 1.0"/>
      </material>
    </visual>
    <collision>
      <origin rpy="-1.57075 0 0" xyz="0 0.07 0"/>
      <geometry>
        <cylinder length="0.14" radius="0.06"/>
      </geometry>
    </collision>
  </link>
  <link name="LL0_femur">
    <inertial>
      <origin rpy="-1.57075 0 0" xyz="0 0.14 0"/>
      <mass value="3.0"/>
      <inertia ixx="0.022300000000000004" ixy="0" ixz="0" iyy="0.022300000000000004" iyz="0" izz="0.005399999999999999"/>
    </inertial>
    <visual>
      <origin rpy="-1.57075 0 0" xyz="0 0.14 0"/>
      <geometry>
        <cylinder length="0.28" radius="0.06"/>
      </geometry>
      <material name="LL0_femur_material">
        <color rgba="0 0.0 0.8 1.0"/>
      </material>
    </visual>
    <collision>
      <origin rpy="-1.57075 0 0" xyz="0 0.14 0"/>
      <geometry>
        <cylinder length="0.28" radius="0.06"/>
      </geometry>
    </collision>
  </link>
  <link name="LL0_tibia">
    <inertial>
      <origin rpy="-1.57075 0 0" xyz="0 0.07 0"/>
      <mass value="0.5"/>
      <inertia ixx="0.0012666666666666668" ixy="0" ixz="0" iyy="0.0012666666666666668" iyz="0" izz="0.0009"/>
    </inertial>
    <visual>
      <origin rpy="-1.57075 0 0" xyz="0 0.07 0"/>
      <geometry>
        <cylinder length="0.14" radius="0.06"/>
      </geometry>
      <material name="LL0_tibia_material">
        <color rgba="0 0.0 0.6 1.0"/>
      </material>
    </visual>
    <collision>
      <origin rpy="-1.57075 0 0" xyz="0 0.07 0"/>
      <geometry>
        <cylinder length="0.14" radius="0.06"/>
      </geometry>
    </collision>
  </link>
  <link name="LL0_wheel">
    <inertial>
      <origin rpy="-1.57075 0 0" xyz="0 0.05 0"/>
      <mass value="0.3"/>
      <inertia ixx="0.004046875" ixy="0" ixz="0" iyy="0.004046875" iyz="0" izz="0.007593750000000001"/>
    </inertial>
    <visual>
      <origin rpy="-1.57075 0 0" xyz="0 0.05 0"/>
      <geometry>
        <cylinder length="0.1" radius="0.225"/>
      </geometry>
      <material name="LL0_wheel_material">
        <color rgba="0 0.5 1.0 1.0"/>
      </material>
    </visual>
    <collision>
      <origin rpy="-1.57075 0 0" xyz="0 0.05 0"/>
      <geometry>
        <cylinder length="0.1" radius="0.225"/>
      </geometry>
    </collision>
  </link>
  <joint name="LL0_TC" type="continuous">
    <parent link="Body0"/>
    <child link="LL0_coxa"/>
    <origin xyz="0.43 0.115 0"/>
    <axis xyz="0 1 0"/>
    <calibration rising="0.0"/>
    <dynamics damping="0" friction="0"/>
  </joint>
  <transmission name="tran_LL0_TC">
    <type>transmission_interface/SimpleTransmission</type>
    <joint name="LL0_TC">
      <hardwareInterface>hardware_interface/EffortJointInterface</hardwareInterface>
    </joint>
    <actuator name="motor_LL0_TC">
      <hardwareInterface>hardware_interface/EffortJointInterface</hardwareInterface>
      <mechanicalReduction>1</mechanicalReduction>
    </actuator>
  </transmission>
  <joint name="LL0_CT" type="continuous">
    <parent link="LL0_coxa"/>
    <child link="LL0_femur"/>
    <origin xyz="0 0.14 0"/>
    <axis xyz="1 0 0"/>
    <calibration rising="0.0"/>
    <dynamics damping="0" friction="0"/>
  </joint>
  <transmission name="tran_LL0_CT">
    <type>transmission_interface/SimpleTransmission</type>
    <joint name="LL0_CT">
      <hardwareInterface>hardware_interface/EffortJointInterface</hardwareInterface>
    </joint>
    <actuator name="motor_LL0_CT">
      <hardwareInterface>hardware_interface/EffortJointInterface</hardwareInterface>
      <mechanicalReduction>1</mechanicalReduction>
    </actuator>
  </transmission>
  <joint name="LL0_FT" type="continuous">
    <parent link="LL0_femur"/>
    <child link="LL0_tibia"/>
    <origin xyz="0 0.28 0"/>
    <axis xyz="1 0 0"/>
    <calibration rising="0.0"/>
    <dynamics damping="0" friction="0"/>
  </joint>
  <transmission name="tran_LL0_FT">
    <type>transmission_interface/SimpleTransmission</type>
    <joint name="LL0_FT">
      <hardwareInterface>hardware_interface/EffortJointInterface</hardwareInterface>
    </joint>
    <actuator name="motor_LL0_FT">
      <hardwareInterface>hardware_interface/EffortJointInterface</hardwareInterface>
      <mechanicalReduction>1</mechanicalReduction>
    </actuator>
  </transmission>
  <joint name="LL0_WH" type="continuous">
    <parent link="LL0_tibia"/>
    <child link="LL0_wheel"/>
    <origin xyz="0 0.14 0"/>
    <axis xyz="0 1 0"/>
    <calibration rising="0.0"/>
    <dynamics damping="0" friction="0"/>
  </joint>
  <transmission name="tran_LL0_WH">
    <type>transmission_interface/SimpleTransmission</type>
    <joint name="LL0_WH">
      <hardwareInterface>hardware_interface/EffortJointInterface</hardwareInterface>
    </joint>
    <actuator name="motor_LL0_WH">
      <hardwareInterface>hardware_interface/EffortJointInterface</hardwareInterface>
      <mechanicalReduction>1</mechanicalReduction>
    </actuator>
  </transmission>
  <link name="LR1_coxa">
    <inertial>
      <origin rpy="1.57075 0 0" xyz="0 -0.07 0"/>
      <mass value="0.5"/>
      <inertia ixx="0.0012666666666666668" ixy="0" ixz="0" iyy="0.0012666666666666668" iyz="0" izz="0.0009"/>
    </inertial>
    <visual>
      <origin rpy="1.57075 0 0" xyz="0 -0.07 0"/>
      <geometry>
        <cylinder length="0.14" radius="0.06"/>
      </geometry>
      <material name="LR1_coxa_material">
        <color rgba="0 0.0 1.0 1.0"/>
      </material>
    </visual>
    <collision>
      <origin rpy="1.57075 0 0" xyz="0 -0.07 0"/>
      <geometry>
        <cylinder length="0.14" radius="0.06"/>
      </geometry>
    </collision>
  </link>
  <link name="LR1_femur">
    <inertial>
      <origin rpy="1.57075 0 0" xyz="0 -0.14 0"/>
      <mass value="3.0"/>
      <inertia ixx="0.022300000000000004" ixy="0" ixz="0" iyy="0.022300000000000004" iyz="0" izz="0.005399999999999999"/>
    </inertial>
    <visual>
      <origin rpy="1.57075 0 0" xyz="0 -0.14 0"/>
      <geometry>
        <cylinder length="0.28" radius="0.06"/>
      </geometry>
      <material name="LR1_femur_material">
        <color rgba="0 0.0 0.8 1.0"/>
      </material>
    </visual>
    <collision>
      <origin rpy="1.57075 0 0" xyz="0 -0.14 0"/>
      <geometry>
        <cylinder length="0.28" radius="0.06"/>
      </geometry>
    </collision>
  </link>
  <link name="LR1_tibia">
    <inertial>
      <origin rpy="1.57075 0 0" xyz="0 -0.07 0"/>
      <mass value="0.5"/>
      <inertia ixx="0.0012666666666666668" ixy="0" ixz="0" iyy="0.0012666666666666668" iyz="0" izz="0.0009"/>
    </inertial>
    <visual>
      <origin rpy="1.57075 0 0" xyz="0 -0.07 0"/>
      <geometry>
        <cylinder length="0.14" radius="0.06"/>
      </geometry>
      <material name="LR1_tibia_material">
        <color rgba="0 0.0 0.6 1.0"/>
      </material>
    </visual>
    <collision>
      <origin rpy="1.57075 0 0" xyz="0 -0.07 0"/>
      <geometry>
        <cylinder length="0.14" radius="0.06"/>
      </geometry>
    </collision>
  </link>
  <link name="LR1_wheel">
    <inertial>
      <origin rpy="1.57075 0 0" xyz="0 -0.05 0"/>
      <mass value="0.3"/>
      <inertia ixx="0.004046875" ixy="0" ixz="0" iyy="0.004046875" iyz="0" izz="0.007593750000000001"/>
    </inertial>
    <visual>
      <origin rpy="1.57075 0 0" xyz="0 -0.05 0"/>
      <geometry>
        <cylinder length="0.1" radius="0.225"/>
      </geometry>
      <material name="LR1_wheel_material">
        <color rgba="0 0.5 1.0 1.0"/>
      </material>
    </visual>
    <collision>
      <origin rpy="1.57075 0 0" xyz="0 -0.05 0"/>
      <geometry>
        <cylinder length="0.1" radius="0.225"/>
      </geometry>
    </collision>
  </link>
  <joint name="LR1_TC" type="continuous">
    <parent link="Body0"/>
    <child link="LR1_coxa"/>
    <origin xyz="0.15 -0.115 0"/>
    <axis xyz="0 1 0"/>
    <calibration rising="0.0"/>
    <dynamics damping="0" friction="0"/>
  </joint>
  <transmission name="tran_LR1_TC">
    <type>transmission_interface/SimpleTransmission</type>
    <joint name="LR1_TC">
      <hardwareInterface>hardware_interface/EffortJointInterface</hardwareInterface>
    </joint>
    <actuator name="motor_LR1_TC">
      <hardwareInterface>hardware_interface/EffortJointInterface</hardwareInterface>
      <mechanicalReduction>1</mechanicalReduction>
    </actuator>
  </transmission>
  <joint name="LR1_CT" type="continuous">
    <parent link="LR1_coxa"/>
    <child link="LR1_femur"/>
    <origin xyz="0 -0.14 0"/>
    <axis xyz="1 0 0"/>
    <calibration rising="0.0"/>
    <dynamics damping="0" friction="0"/>
  </joint>
  <transmission name="tran_LR1_CT">
    <type>transmission_interface/SimpleTransmission</type>
    <joint name="LR1_CT">
      <hardwareInterface>hardware_interface/EffortJointInterface</hardwareInterface>
    </joint>
    <actuator name="motor_LR1_CT">
      <hardwareInterface>hardware_interface/EffortJointInterface</hardwareInterface>
      <mechanicalReduction>1</mechanicalReduction>
    </actuator>
  </transmission>
  <joint name="LR1_FT" type="continuous">
    <parent link="LR1_femur"/>
    <child link="LR1_tibia"/>
    <origin xyz="0 -0.28 0"/>
    <axis xyz="1 0 0"/>
    <calibration rising="0.0"/>
    <dynamics damping="0" friction="0"/>
  </joint>
  <transmission name="tran_LR1_FT">
    <type>transmission_interface/SimpleTransmission</type>
    <joint name="LR1_FT">
      <hardwareInterface>hardware_interface/EffortJointInterface</hardwareInterface>
    </joint>
    <actuator name="motor_LR1_FT">
      <hardwareInterface>hardware_interface/EffortJointInterface</hardwareInterface>
      <mechanicalReduction>1</mechanicalReduction>
    </actuator>
  </transmission>
  <joint name="LR1_WH" type="continuous">
    <parent link="LR1_tibia"/>
    <child link="LR1_wheel"/>
    <origin xyz="0 -0.14 0"/>
    <axis xyz="0 1 0"/>
    <calibration rising="0.0"/>
    <dynamics damping="0" friction="0"/>
  </joint>
  <transmission name="tran_LR1_WH">
    <type>transmission_interface/SimpleTransmission</type>
    <joint name="LR1_WH">
      <hardwareInterface>hardware_interface/EffortJointInterface</hardwareInterface>
    </joint>
    <actuator name="motor_LR1_WH">
      <hardwareInterface>hardware_interface/EffortJointInterface</hardwareInterface>
      <mechanicalReduction>1</mechanicalReduction>
    </actuator>
  </transmission>
  <link name="LL1_coxa">
    <inertial>
      <origin rpy="-1.57075 0 0" xyz="0 0.07 0"/>
      <mass value="0.5"/>
      <inertia ixx="0.0012666666666666668" ixy="0" ixz="0" iyy="0.0012666666666666668" iyz="0" izz="0.0009"/>
    </inertial>
    <visual>
      <origin rpy="-1.57075 0 0" xyz="0 0.07 0"/>
      <geometry>
        <cylinder length="0.14" radius="0.06"/>
      </geometry>
      <material name="LL1_coxa_material">
        <color rgba="0 0.0 1.0 1.0"/>
      </material>
    </visual>
    <collision>
      <origin rpy="-1.57075 0 0" xyz="0 0.07 0"/>
      <geometry>
        <cylinder length="0.14" radius="0.06"/>
      </geometry>
    </collision>
  </link>
  <link name="LL1_femur">
    <inertial>
      <origin rpy="-1.57075 0 0" xyz="0 0.14 0"/>
      <mass value="3.0"/>
      <inertia ixx="0.022300000000000004" ixy="0" ixz="0" iyy="0.022300000000000004" iyz="0" izz="0.005399999999999999"/>
    </inertial>
    <visual>
      <origin rpy="-1.57075 0 0" xyz="0 0.14 0"/>
      <geometry>
        <cylinder length="0.28" radius="0.06"/>
      </geometry>
      <material name="LL1_femur_material">
        <color rgba="0 0.0 0.8 1.0"/>
      </material>
    </visual>
    <collision>
      <origin rpy="-1.57075 0 0" xyz="0 0.14 0"/>
      <geometry>
        <cylinder length="0.28" radius="0.06"/>
      </geometry>
    </collision>
  </link>
  <link name="LL1_tibia">
    <inertial>
      <origin rpy="-1.57075 0 0" xyz="0 0.07 0"/>
      <mass value="0.5"/>
      <inertia ixx="0.0012666666666666668" ixy="0" ixz="0" iyy="0.0012666666666666668" iyz="0" izz="0.0009"/>
    </inertial>
    <visual>
      <origin rpy="-1.57075 0 0" xyz="0 0.07 0"/>
      <geometry>
        <cylinder length="0.14" radius="0.06"/>
      </geometry>
      <material name="LL1_tibia_material">
        <color rgba="0 0.0 0.6 1.0"/>
      </material>
    </visual>
    <collision>
      <origin rpy="-1.57075 0 0" xyz="0 0.07 0"/>
      <geometry>
        <cylinder length="0.14" radius="0.06"/>
      </geometry>
    </collision>
  </link>
  <link name="LL1_wheel">
    <inertial>
      <origin rpy="-1.57075 0 0" xyz="0 0.05 0"/>
      <mass value="0.3"/>
      <inertia ixx="0.004046875" ixy="0" ixz="0" iyy="0.004046875" iyz="0" izz="0.007593750000000001"/>
    </inertial>
    <visual>
      <origin rpy="-1.57075 0 0" xyz="0 0.05 0"/>
      <geometry>
        <cylinder length="0.1" radius="0.225"/>
      </geometry>
      <material name="LL1_wheel_material">
        <color rgba="0 0.5 1.0 1.0"/>
      </material>
    </visual>
    <collision>
      <origin rpy="-1.57075 0 0" xyz="0 0.05 0"/>
      <geometry>
        <cylinder length="0.1" radius="0.225"/>
      </geometry>
    </collision>
  </link>
  <joint name="LL1_TC" type="continuous">
    <parent link="Body0"/>
    <child link="LL1_coxa"/>
    <origin xyz="0.15 0.115 0"/>
    <axis xyz="0 1 0"/>
    <calibration rising="0.0"/>
    <dynamics damping="0" friction="0"/>
  </joint>
  <transmission name="tran_LL1_TC">
    <type>transmission_interface/SimpleTransmission</type>
    <joint name="LL1_TC">
      <hardwareInterface>hardware_interface/EffortJointInterface</hardwareInterface>
    </joint>
    <actuator name="motor_LL1_TC">
      <hardwareInterface>hardware_interface/EffortJointInterface</hardwareInterface>
      <mechanicalReduction>1</mechanicalReduction>
    </actuator>
  </transmission>
  <joint name="LL1_CT" type="continuous">
    <parent link="LL1_coxa"/>
    <child link="LL1_femur"/>
    <origin xyz="0 0.14 0"/>
    <axis xyz="1 0 0"/>
    <calibration rising="0.0"/>
    <dynamics damping="0" friction="0"/>
  </joint>
  <transmission name="tran_LL1_CT">
    <type>transmission_interface/SimpleTransmission</type>
    <joint name="LL1_CT">
      <hardwareInterface>hardware_interface/EffortJointInterface</hardwareInterface>
    </joint>
    <actuator name="motor_LL1_CT">
      <hardwareInterface>hardware_interface/EffortJointInterface</hardwareInterface>
      <mechanicalReduction>1</mechanicalReduction>
    </actuator>
  </transmission>
  <joint name="LL1_FT" type="continuous">
    <parent link="LL1_femur"/>
    <child link="LL1_tibia"/>
    <origin xyz="0 0.28 0"/>
    <axis xyz="1 0 0"/>
    <calibration rising="0.0"/>
    <dynamics damping="0" friction="0"/>
  </joint>
  <transmission name="tran_LL1_FT">
    <type>transmission_interface/SimpleTransmission</type>
    <joint name="LL1_FT">
      <hardwareInterface>hardware_interface/EffortJointInterface</hardwareInterface>
    </joint>
    <actuator name="motor_LL1_FT">
      <hardwareInterface>hardware_interface/EffortJointInterface</hardwareInterface>
      <mechanicalReduction>1</mechanicalReduction>
    </actuator>
  </transmission>
  <joint name="LL1_WH" type="continuous">
    <parent link="LL1_tibia"/>
    <child link="LL1_wheel"/>
    <origin xyz="0 0.14 0"/>
    <axis xyz="0 1 0"/>
    <calibration rising="0.0"/>
    <dynamics damping="0" friction="0"/>
  </joint>
  <transmission name="tran_LL1_WH">
    <type>transmission_interface/SimpleTransmission</type>
    <joint name="LL1_WH">
      <hardwareInterface>hardware_interface/EffortJointInterface</hardwareInterface>
    </joint>
    <actuator name="motor_LL1_WH">
      <hardwareInterface>hardware_interface/EffortJointInterface</hardwareInterface>
      <mechanicalReduction>1</mechanicalReduction>
    </actuator>
  </transmission>
  <link name="LF0_coxa">
    <inertial>
      <origin rpy="0 1.57075 0" xyz="0.07 0 0"/>
      <mass value="0.5"/>
      <inertia ixx="0.0012666666666666668" ixy="0" ixz="0" iyy="0.0012666666666666668" iyz="0" izz="0.0009"/>
    </inertial>
    <visual>
      <origin rpy="0 1.57075 0" xyz="0.07 0 0"/>
      <geometry>
        <cylinder length="0.14" radius="0.06"/>
      </geometry>
      <material name="LF0_coxa_material">
        <color rgba="0 0.0 1.0 1.0"/>
      </material>
    </visual>
    <collision>
      <origin rpy="0 1.57075 0" xyz="0.07 0 0"/>
      <geometry>
        <cylinder length="0.14" radius="0.06"/>
      </geometry>
    </collision>
  </link>
  <link name="LF0_femur">
    <inertial>
      <origin rpy="0 1.57075  0" xyz="0.14 0 0"/>
      <mass value="3.0"/>
      <inertia ixx="0.022300000000000004" ixy="0" ixz="0" iyy="0.022300000000000004" iyz="0" izz="0.005399999999999999"/>
    </inertial>
    <visual>
      <origin rpy="0 1.57075  0" xyz="0.14 0 0"/>
      <geometry>
        <cylinder length="0.28" radius="0.06"/>
      </geometry>
      <material name="LF0_femur_material">
        <color rgba="0 0.0 0.8 1.0"/>
      </material>
    </visual>
    <collision>
      <origin rpy="0 1.57075  0" xyz="0.14 0 0"/>
      <geometry>
        <cylinder length="0.28" radius="0.06"/>
      </geometry>
    </collision>
  </link>
  <link name="LF0_tibia">
    <inertial>
      <origin rpy="0 1.57075  0" xyz="0.07 0 0"/>
      <mass value="0.5"/>
      <inertia ixx="0.0012666666666666668" ixy="0" ixz="0" iyy="0.0012666666666666668" iyz="0" izz="0.0009"/>
    </inertial>
    <visual>
      <origin rpy="0 1.57075  0" xyz="0.07 0 0"/>
      <geometry>
        <cylinder length="0.14" radius="0.06"/>
      </geometry>
      <material name="LF0_tibia_material">
        <color rgba="0 0.0 0.6 1.0"/>
      </material>
    </visual>
    <collision>
      <origin rpy="0 1.57075  0" xyz="0.07 0 0"/>
      <geometry>
        <cylinder length="0.14" radius="0.06"/>
      </geometry>
    </collision>
  </link>
  <link name="LF0_wheel">
    <inertial>
      <origin rpy="0 1.57075  0" xyz="0.05 0 0"/>
      <mass value="0.3"/>
      <inertia ixx="0.004046875" ixy="0" ixz="0" iyy="0.004046875" iyz="0" izz="0.007593750000000001"/>
    </inertial>
    <visual>
      <origin rpy="0 1.57075  0" xyz="0.05 0 0"/>
      <geometry>
        <cylinder length="0.1" radius="0.225"/>
      </geometry>
      <material name="LF0_wheel_material">
        <color rgba="0 0.5 1.0 1.0"/>
      </material>
    </visual>
    <collision>
      <origin rpy="0 1.57075  0" xyz="0.05 0 0"/>
      <geometry>
        <cylinder length="0.1" radius="0.225"/>
      </geometry>
    </collision>
  </link>
  <joint name="LF0_TC" type="continuous">
    <parent link="Body0"/>
    <child link="LF0_coxa"/>
    <origin xyz="0.58 0 0"/>
    <axis xyz="1 0 0"/>
    <calibration rising="0.0"/>
    <dynamics damping="0" friction="0"/>
  </joint>
  <transmission name="tran_LF0_TC">
    <type>transmission_interface/SimpleTransmission</type>
    <joint name="LF0_TC">
      <hardwareInterface>hardware_interface/EffortJointInterface</hardwareInterface>
    </joint>
    <actuator name="motor_LF0_TC">
      <hardwareInterface>hardware_interface/EffortJointInterface</hardwareInterface>
      <mechanicalReduction>1</mechanicalReduction>
    </actuator>
  </transmission>
  <joint name="LF0_CT" type="continuous">
    <parent link="LF0_coxa"/>
    <child link="LF0_femur"/>
    <origin xyz="0.14 0 0"/>
    <axis xyz="0 1 0"/>
    <calibration rising="0.0"/>
    <dynamics damping="0" friction="0"/>
  </joint>
  <transmission name="tran_LF0_CT">
    <type>transmission_interface/SimpleTransmission</type>
    <joint name="LF0_CT">
      <hardwareInterface>hardware_interface/EffortJointInterface</hardwareInterface>
    </joint>
    <actuator name="motor_LF0_CT">
      <hardwareInterface>hardware_interface/EffortJointInterface</hardwareInterface>
      <mechanicalReduction>1</mechanicalReduction>
    </actuator>
  </transmission>
  <joint name="LF0_FT" type="continuous">
    <parent link="LF0_femur"/>
    <child link="LF0_tibia"/>
    <origin xyz="0.28 0 0"/>
    <axis xyz="0 1 0"/>
    <calibration rising="0.0"/>
    <dynamics damping="0" friction="0"/>
  </joint>
  <transmission name="tran_LF0_FT">
    <type>transmission_interface/SimpleTransmission</type>
    <joint name="LF0_FT">
      <hardwareInterface>hardware_interface/EffortJointInterface</hardwareInterface>
    </joint>
    <actuator name="motor_LF0_FT">
      <hardwareInterface>hardware_interface/EffortJointInterface</hardwareInterface>
      <mechanicalReduction>1</mechanicalReduction>
    </actuator>
  </transmission>
  <joint name="LF0_WH" type="continuous">
    <parent link="LF0_tibia"/>
    <child link="LF0_wheel"/>
    <origin xyz="0.14 0 0"/>
    <axis xyz="1 0 0"/>
    <calibration rising="0.0"/>
    <dynamics damping="0" friction="0"/>
  </joint>
  <transmission name="tran_LF0_WH">
    <type>transmission_interface/SimpleTransmission</type>
    <joint name="LF0_WH">
      <hardwareInterface>hardware_interface/EffortJointInterface</hardwareInterface>
    </joint>
    <actuator name="motor_LF0_WH">
      <hardwareInterface>hardware_interface/EffortJointInterface</hardwareInterface>
      <mechanicalReduction>1</mechanicalReduction>
    </actuator>
  </transmission>


  <gazebo reference="LL0_wheel">
    <material>Gazebo/Red</material>
    <selfCollide>true</selfCollide>
    <mu1> 0.1 </mu1>
    <mu2> 0.1 </mu2>
    <maxVel> 1.0 </maxVel>
    <minDepth>0.001</minDepth>
    <kp>50.0</kp>
    <kd>1.0</kd>
  </gazebo>
  <gazebo reference="LL1_wheel">
    <material>Gazebo/Red</material>
    <selfCollide>true</selfCollide>
    <mu1> 0.1 </mu1>
    <mu2> 0.1 </mu2>
    <maxVel> 1.0 </maxVel>
    <minDepth>0.001</minDepth>
    <kp>50.0</kp>
    <kd>1.0</kd>
  </gazebo>
  <gazebo reference="LR0_wheel">
    <material>Gazebo/Red</material>
    <selfCollide>true</selfCollide>
    <mu1> 0.1 </mu1>
    <mu2> 0.1 </mu2>
    <maxVel> 1.0 </maxVel>
    <minDepth>0.001</minDepth>
    <kp>50.0</kp>
    <kd>1.0</kd>
  </gazebo>
  <gazebo reference="LR1_wheel">
    <material>Gazebo/Red</material>
    <selfCollide>true</selfCollide>
    <mu1> 0.1 </mu1>
    <mu2> 0.1 </mu2>
    <maxVel> 1.0 </maxVel>
    <minDepth>0.001</minDepth>
    <kp>50.0</kp>
    <kd>1.0</kd>
  </gazebo>
  <gazebo reference="LF0_wheel">
    <material>Gazebo/Red</material>
    <selfCollide>true</selfCollide>
    <mu1> 0.1 </mu1>
    <mu2> 0.1 </mu2>
    <maxVel> 1.0 </maxVel>
    <minDepth>0.001</minDepth>
    <kp>50.0</kp>
    <kd>1.0</kd>
  </gazebo>

 <!-- ros_control plugin -->
  <!-- ros2_control -->
  <ros2_control name="IgnitionSystem" type="system">
    <hardware>
      <plugin>ign_ros2_control/IgnitionSystem</plugin>
    </hardware>
 
      <!-- Rev Link Right side -->
    <joint name="LR0_TC">
      <command_interface name="effort">
        <param name="min">-100</param>
        <param name="max">100</param>
      </command_interface>
      <state_interface name="position"/>
      <state_interface name="velocity"/>
      <state_interface name="effort"/>
    </joint>
    <joint name="LR0_CT">
      <command_interface name="effort">
        <param name="min">-100</param>
        <param name="max">100</param>
      </command_interface>
      <state_interface name="position"/>
      <state_interface name="velocity"/>
      <state_interface name="effort"/>
    </joint>
    <joint name="LR0_FT">
      <command_interface name="effort">
        <param name="min">-100</param>
        <param name="max">100</param>
      </command_interface>
      <state_interface name="position"/>
      <state_interface name="velocity"/>
      <state_interface name="effort"/>
    </joint>
    <joint name="LR0_WH">
      <command_interface name="effort">
        <param name="min">-100</param>
        <param name="max">100</param>
      </command_interface>
      <state_interface name="position"/>
      <state_interface name="velocity"/>
      <state_interface name="effort"/>
    </joint>

    <joint name="LR1_TC">
      <command_interface name="effort">
        <param name="min">-100</param>
        <param name="max">100</param>
      </command_interface>
      <state_interface name="position"/>
      <state_interface name="velocity"/>
      <state_interface name="effort"/>
    </joint>
    <joint name="LR1_CT">
      <command_interface name="effort">
        <param name="min">-100</param>
        <param name="max">100</param>
      </command_interface>
      <state_interface name="position"/>
      <state_interface name="velocity"/>
      <state_interface name="effort"/>
    </joint>
    <joint name="LR1_FT">
      <command_interface name="effort">
        <param name="min">-100</param>
        <param name="max">100</param>
      </command_interface>
      <state_interface name="position"/>
      <state_interface name="velocity"/>
      <state_interface name="effort"/>
    </joint>
    <joint name="LR1_WH">
      <command_interface name="effort">
        <param name="min">-100</param>
        <param name="max">100</param>
      </command_interface>
      <state_interface name="position"/>
      <state_interface name="velocity"/>
      <state_interface name="effort"/>
    </joint>


     <!-- Rev Link Left side -->
    <joint name="LL0_TC">
      <command_interface name="effort">
        <param name="min">-100</param>
        <param name="max">100</param>
      </command_interface>
      <state_interface name="position"/>
      <state_interface name="velocity"/>
      <state_interface name="effort"/>
    </joint>
    <joint name="LL0_CT">
      <command_interface name="effort">
        <param name="min">-100</param>
        <param name="max">100</param>
      </command_interface>
      <state_interface name="position"/>
      <state_interface name="velocity"/>
      <state_interface name="effort"/>
    </joint>
    <joint name="LL0_FT">
      <command_interface name="effort">
        <param name="min">-100</param>
        <param name="max">100</param>
      </command_interface>
      <state_interface name="position"/>
      <state_interface name="velocity"/>
      <state_interface name="effort"/>
    </joint>
    <joint name="LL0_WH">
      <command_interface name="effort">
        <param name="min">-100</param>
        <param name="max">100</param>
      </command_interface>
      <state_interface name="position"/>
      <state_interface name="velocity"/>
      <state_interface name="effort"/>
    </joint>

    <joint name="LL1_TC">
      <command_interface name="effort">
        <param name="min">-100</param>
        <param name="max">100</param>
      </command_interface>
      <state_interface name="position"/>
      <state_interface name="velocity"/>
      <state_interface name="effort"/>
    </joint>
    <joint name="LL1_CT">
      <command_interface name="effort">
        <param name="min">-100</param>
        <param name="max">100</param>
      </command_interface>
      <state_interface name="position"/>
      <state_interface name="velocity"/>
      <state_interface name="effort"/>
    </joint>
    <joint name="LL1_FT">
      <command_interface name="effort">
        <param name="min">-100</param>
        <param name="max">100</param>
      </command_interface>
      <state_interface name="position"/>
      <state_interface name="velocity"/>
      <state_interface name="effort"/>
    </joint>
    <joint name="LL1_WH">
      <command_interface name="effort">
        <param name="min">-100</param>
        <param name="max">100</param>
      </command_interface>
      <state_interface name="position"/>
      <state_interface name="velocity"/>
      <state_interface name="effort"/>
    </joint>

  <!-- Rev Link Fore Hind side -->
    <joint name="LF0_TC">
      <command_interface name="effort">
        <param name="min">-100</param>
        <param name="max">100</param>
      </command_interface>
      <state_interface name="position"/>
      <state_interface name="velocity"/>
      <state_interface name="effort"/>
    </joint>
    <joint name="LF0_CT">
      <command_interface name="effort">
        <param name="min">-100</param>
        <param name="max">100</param>
      </command_interface>
      <state_interface name="position"/>
      <state_interface name="velocity"/>
      <state_interface name="effort"/>
    </joint>
    <joint name="LF0_FT">
      <command_interface name="effort">
        <param name="min">-100</param>
        <param name="max">100</param>
      </command_interface>
      <state_interface name="position"/>
      <state_interface name="velocity"/>
      <state_interface name="effort"/>
    </joint>
    <joint name="LF0_WH">
      <command_interface name="effort">
        <param name="min">-100</param>
        <param name="max">100</param>
      </command_interface>
      <state_interface name="position"/>
      <state_interface name="velocity"/>
      <state_interface name="effort"/>
    </joint>
  </ros2_control>

  <!-- ros_control plugin -->
  <gazebo>
    <!-- <plugin filename="libgazebo_ros2_control.so" name="gazebo_ros2_control"> -->
    <plugin name="ign_ros2_control::IgnitionROS2ControlPlugin" filename="ign_ros2_control-system">     <!-- <robot_param>robot_description</robot_param> -->
     <!-- <robot_param_node>robot_state_publisher</robot_param_node> -->
      <!-- <parameters>$(find manta_v2_gazebo_ros2_control)/config/manta_v2_moveit_controller.yaml</parameters> -->
     <parameters>$(find robot_gazebo_ros2_control)/config/robot_trajectory_controller_5wheel.yaml</parameters>  
      <!--<parameters>$(find robot_gazebo_ros2_control)/config/robot_effort_controller.yaml</parameters> -->
     <controller_manager_prefix_node_name>controller_manager</controller_manager_prefix_node_name>
    </plugin>
  </gazebo>

  <!-- Color body -->
  <gazebo reference="Body0">
    <material>Gazebo/Black</material>
  </gazebo>
  <!--
    <gazebo reference="Body1">
        <material>Gazebo/Black</material>
    </gazebo>
    <gazebo reference="Body2">
        <material>Gazebo/Black</material>
    </gazebo>
    <gazebo reference="Body3">
        <material>Gazebo/Black</material>
    </gazebo>
    <gazebo reference="Body4">
        <material>Gazebo/Black</material>
    </gazebo>
    -->
</robot>
